2019-10-18 04:55:31,184 -  nornir.core -     INFO -        run() - Running task 'netmiko_direct' with args {} on 9 hosts
2019-10-18 05:07:45,682 -  nornir.core -  WARNING -        run() - Task 'netmiko_direct' has not been run – 0 hosts selected
2019-10-18 05:09:27,569 -  nornir.core -     INFO -        run() - Running task 'netmiko_direct' with args {} on 9 hosts
2019-10-18 05:09:30,312 - nornir.core.task -    ERROR -      start() - Host 'cisco3': task 'netmiko_direct' failed with traceback:
Traceback (most recent call last):
  File "/home/petrache/VENV/py3_venv/local/lib/python3.6/site-packages/netmiko/base_connection.py", line 869, in establish_connection
    self.remote_conn_pre.connect(**ssh_connect_params)
  File "/home/petrache/VENV/py3_venv/local/lib/python3.6/site-packages/paramiko/client.py", line 446, in connect
    passphrase,
  File "/home/petrache/VENV/py3_venv/local/lib/python3.6/site-packages/paramiko/client.py", line 764, in _auth
    raise saved_exception
  File "/home/petrache/VENV/py3_venv/local/lib/python3.6/site-packages/paramiko/client.py", line 751, in _auth
    self._transport.auth_password(username, password)
  File "/home/petrache/VENV/py3_venv/local/lib/python3.6/site-packages/paramiko/transport.py", line 1509, in auth_password
    return self.auth_handler.wait_for_response(my_event)
  File "/home/petrache/VENV/py3_venv/local/lib/python3.6/site-packages/paramiko/auth_handler.py", line 236, in wait_for_response
    raise e
paramiko.ssh_exception.AuthenticationException: Authentication failed.

During handling of the above exception, another exception occurred:

Traceback (most recent call last):
  File "/home/petrache/VENV/py3_venv/local/lib/python3.6/site-packages/nornir/core/task.py", line 67, in start
    r = self.task(self, **self.params)
  File "exercise3.py", line 9, in netmiko_direct
    net_connect = task.host.get_connection("netmiko", task.nornir.config)
  File "/home/petrache/VENV/py3_venv/local/lib/python3.6/site-packages/nornir/core/inventory.py", line 302, in get_connection
    extras=conn.extras,
  File "/home/petrache/VENV/py3_venv/local/lib/python3.6/site-packages/nornir/core/inventory.py", line 352, in open_connection
    configuration=configuration,
  File "/home/petrache/VENV/py3_venv/local/lib/python3.6/site-packages/nornir/plugins/connections/netmiko.py", line 58, in open
    self.connection = ConnectHandler(**parameters)
  File "/home/petrache/VENV/py3_venv/local/lib/python3.6/site-packages/netmiko/ssh_dispatcher.py", line 243, in ConnectHandler
    return ConnectionClass(*args, **kwargs)
  File "/home/petrache/VENV/py3_venv/local/lib/python3.6/site-packages/netmiko/base_connection.py", line 317, in __init__
    self._open()
  File "/home/petrache/VENV/py3_venv/local/lib/python3.6/site-packages/netmiko/base_connection.py", line 322, in _open
    self.establish_connection()
  File "/home/petrache/VENV/py3_venv/local/lib/python3.6/site-packages/netmiko/base_connection.py", line 882, in establish_connection
    raise NetMikoAuthenticationException(msg)
netmiko.ssh_exception.NetMikoAuthenticationException: Authentication failure: unable to connect cisco_ios cisco3.lasthop.io:22
Authentication failed.

2019-10-18 05:09:32,756 - nornir.core.task -    ERROR -      start() - Host 'cisco4': task 'netmiko_direct' failed with traceback:
Traceback (most recent call last):
  File "/home/petrache/VENV/py3_venv/local/lib/python3.6/site-packages/netmiko/base_connection.py", line 869, in establish_connection
    self.remote_conn_pre.connect(**ssh_connect_params)
  File "/home/petrache/VENV/py3_venv/local/lib/python3.6/site-packages/paramiko/client.py", line 446, in connect
    passphrase,
  File "/home/petrache/VENV/py3_venv/local/lib/python3.6/site-packages/paramiko/client.py", line 764, in _auth
    raise saved_exception
  File "/home/petrache/VENV/py3_venv/local/lib/python3.6/site-packages/paramiko/client.py", line 751, in _auth
    self._transport.auth_password(username, password)
  File "/home/petrache/VENV/py3_venv/local/lib/python3.6/site-packages/paramiko/transport.py", line 1509, in auth_password
    return self.auth_handler.wait_for_response(my_event)
  File "/home/petrache/VENV/py3_venv/local/lib/python3.6/site-packages/paramiko/auth_handler.py", line 236, in wait_for_response
    raise e
paramiko.ssh_exception.AuthenticationException: Authentication failed.

During handling of the above exception, another exception occurred:

Traceback (most recent call last):
  File "/home/petrache/VENV/py3_venv/local/lib/python3.6/site-packages/nornir/core/task.py", line 67, in start
    r = self.task(self, **self.params)
  File "exercise3.py", line 9, in netmiko_direct
    net_connect = task.host.get_connection("netmiko", task.nornir.config)
  File "/home/petrache/VENV/py3_venv/local/lib/python3.6/site-packages/nornir/core/inventory.py", line 302, in get_connection
    extras=conn.extras,
  File "/home/petrache/VENV/py3_venv/local/lib/python3.6/site-packages/nornir/core/inventory.py", line 352, in open_connection
    configuration=configuration,
  File "/home/petrache/VENV/py3_venv/local/lib/python3.6/site-packages/nornir/plugins/connections/netmiko.py", line 58, in open
    self.connection = ConnectHandler(**parameters)
  File "/home/petrache/VENV/py3_venv/local/lib/python3.6/site-packages/netmiko/ssh_dispatcher.py", line 243, in ConnectHandler
    return ConnectionClass(*args, **kwargs)
  File "/home/petrache/VENV/py3_venv/local/lib/python3.6/site-packages/netmiko/base_connection.py", line 317, in __init__
    self._open()
  File "/home/petrache/VENV/py3_venv/local/lib/python3.6/site-packages/netmiko/base_connection.py", line 322, in _open
    self.establish_connection()
  File "/home/petrache/VENV/py3_venv/local/lib/python3.6/site-packages/netmiko/base_connection.py", line 882, in establish_connection
    raise NetMikoAuthenticationException(msg)
netmiko.ssh_exception.NetMikoAuthenticationException: Authentication failure: unable to connect cisco_ios cisco4.lasthop.io:22
Authentication failed.

2019-10-18 05:11:31,955 -  nornir.core -  WARNING -        run() - Task 'netmiko_direct' has not been run – 0 hosts selected
2019-10-18 05:12:07,424 -  nornir.core -  WARNING -        run() - Task 'netmiko_direct' has not been run – 0 hosts selected
2019-10-18 05:12:28,400 -  nornir.core -  WARNING -        run() - Task 'netmiko_direct' has not been run – 0 hosts selected
2019-10-18 05:13:27,425 -  nornir.core -     INFO -        run() - Running task 'netmiko_direct' with args {} on 1 hosts
2019-10-18 05:14:32,377 -  nornir.core -     INFO -        run() - Running task 'netmiko_direct' with args {} on 9 hosts
2019-10-18 05:14:42,496 - nornir.core.task -    ERROR -      start() - Host 'nxos1': task 'netmiko_direct' failed with traceback:
Traceback (most recent call last):
  File "/home/petrache/VENV/py3_venv/local/lib/python3.6/site-packages/nornir/core/task.py", line 67, in start
    r = self.task(self, **self.params)
  File "exercise3.py", line 9, in netmiko_direct
    net_connect = task.host.get_connection("netmiko", task.nornir.config)
  File "/home/petrache/VENV/py3_venv/local/lib/python3.6/site-packages/nornir/core/inventory.py", line 302, in get_connection
    extras=conn.extras,
  File "/home/petrache/VENV/py3_venv/local/lib/python3.6/site-packages/nornir/core/inventory.py", line 352, in open_connection
    configuration=configuration,
  File "/home/petrache/VENV/py3_venv/local/lib/python3.6/site-packages/nornir/plugins/connections/netmiko.py", line 58, in open
    self.connection = ConnectHandler(**parameters)
  File "/home/petrache/VENV/py3_venv/local/lib/python3.6/site-packages/netmiko/ssh_dispatcher.py", line 243, in ConnectHandler
    return ConnectionClass(*args, **kwargs)
  File "/home/petrache/VENV/py3_venv/local/lib/python3.6/site-packages/netmiko/base_connection.py", line 317, in __init__
    self._open()
  File "/home/petrache/VENV/py3_venv/local/lib/python3.6/site-packages/netmiko/base_connection.py", line 322, in _open
    self.establish_connection()
  File "/home/petrache/VENV/py3_venv/local/lib/python3.6/site-packages/netmiko/base_connection.py", line 869, in establish_connection
    self.remote_conn_pre.connect(**ssh_connect_params)
  File "/home/petrache/VENV/py3_venv/local/lib/python3.6/site-packages/paramiko/client.py", line 446, in connect
    passphrase,
  File "/home/petrache/VENV/py3_venv/local/lib/python3.6/site-packages/paramiko/client.py", line 765, in _auth
    raise SSHException("No authentication methods available")
paramiko.ssh_exception.SSHException: No authentication methods available

2019-10-18 05:14:42,833 - nornir.core.task -    ERROR -      start() - Host 'nxos2': task 'netmiko_direct' failed with traceback:
Traceback (most recent call last):
  File "/home/petrache/VENV/py3_venv/local/lib/python3.6/site-packages/nornir/core/task.py", line 67, in start
    r = self.task(self, **self.params)
  File "exercise3.py", line 9, in netmiko_direct
    net_connect = task.host.get_connection("netmiko", task.nornir.config)
  File "/home/petrache/VENV/py3_venv/local/lib/python3.6/site-packages/nornir/core/inventory.py", line 302, in get_connection
    extras=conn.extras,
  File "/home/petrache/VENV/py3_venv/local/lib/python3.6/site-packages/nornir/core/inventory.py", line 352, in open_connection
    configuration=configuration,
  File "/home/petrache/VENV/py3_venv/local/lib/python3.6/site-packages/nornir/plugins/connections/netmiko.py", line 58, in open
    self.connection = ConnectHandler(**parameters)
  File "/home/petrache/VENV/py3_venv/local/lib/python3.6/site-packages/netmiko/ssh_dispatcher.py", line 243, in ConnectHandler
    return ConnectionClass(*args, **kwargs)
  File "/home/petrache/VENV/py3_venv/local/lib/python3.6/site-packages/netmiko/base_connection.py", line 317, in __init__
    self._open()
  File "/home/petrache/VENV/py3_venv/local/lib/python3.6/site-packages/netmiko/base_connection.py", line 322, in _open
    self.establish_connection()
  File "/home/petrache/VENV/py3_venv/local/lib/python3.6/site-packages/netmiko/base_connection.py", line 869, in establish_connection
    self.remote_conn_pre.connect(**ssh_connect_params)
  File "/home/petrache/VENV/py3_venv/local/lib/python3.6/site-packages/paramiko/client.py", line 446, in connect
    passphrase,
  File "/home/petrache/VENV/py3_venv/local/lib/python3.6/site-packages/paramiko/client.py", line 765, in _auth
    raise SSHException("No authentication methods available")
paramiko.ssh_exception.SSHException: No authentication methods available

2019-10-18 05:14:43,271 - nornir.core.task -    ERROR -      start() - Host 'arista1': task 'netmiko_direct' failed with traceback:
Traceback (most recent call last):
  File "/home/petrache/VENV/py3_venv/local/lib/python3.6/site-packages/nornir/core/task.py", line 67, in start
    r = self.task(self, **self.params)
  File "exercise3.py", line 9, in netmiko_direct
    net_connect = task.host.get_connection("netmiko", task.nornir.config)
  File "/home/petrache/VENV/py3_venv/local/lib/python3.6/site-packages/nornir/core/inventory.py", line 302, in get_connection
    extras=conn.extras,
  File "/home/petrache/VENV/py3_venv/local/lib/python3.6/site-packages/nornir/core/inventory.py", line 352, in open_connection
    configuration=configuration,
  File "/home/petrache/VENV/py3_venv/local/lib/python3.6/site-packages/nornir/plugins/connections/netmiko.py", line 58, in open
    self.connection = ConnectHandler(**parameters)
  File "/home/petrache/VENV/py3_venv/local/lib/python3.6/site-packages/netmiko/ssh_dispatcher.py", line 243, in ConnectHandler
    return ConnectionClass(*args, **kwargs)
  File "/home/petrache/VENV/py3_venv/local/lib/python3.6/site-packages/netmiko/base_connection.py", line 317, in __init__
    self._open()
  File "/home/petrache/VENV/py3_venv/local/lib/python3.6/site-packages/netmiko/base_connection.py", line 322, in _open
    self.establish_connection()
  File "/home/petrache/VENV/py3_venv/local/lib/python3.6/site-packages/netmiko/base_connection.py", line 869, in establish_connection
    self.remote_conn_pre.connect(**ssh_connect_params)
  File "/home/petrache/VENV/py3_venv/local/lib/python3.6/site-packages/paramiko/client.py", line 446, in connect
    passphrase,
  File "/home/petrache/VENV/py3_venv/local/lib/python3.6/site-packages/paramiko/client.py", line 765, in _auth
    raise SSHException("No authentication methods available")
paramiko.ssh_exception.SSHException: No authentication methods available

2019-10-18 05:14:43,776 - nornir.core.task -    ERROR -      start() - Host 'arista2': task 'netmiko_direct' failed with traceback:
Traceback (most recent call last):
  File "/home/petrache/VENV/py3_venv/local/lib/python3.6/site-packages/nornir/core/task.py", line 67, in start
    r = self.task(self, **self.params)
  File "exercise3.py", line 9, in netmiko_direct
    net_connect = task.host.get_connection("netmiko", task.nornir.config)
  File "/home/petrache/VENV/py3_venv/local/lib/python3.6/site-packages/nornir/core/inventory.py", line 302, in get_connection
    extras=conn.extras,
  File "/home/petrache/VENV/py3_venv/local/lib/python3.6/site-packages/nornir/core/inventory.py", line 352, in open_connection
    configuration=configuration,
  File "/home/petrache/VENV/py3_venv/local/lib/python3.6/site-packages/nornir/plugins/connections/netmiko.py", line 58, in open
    self.connection = ConnectHandler(**parameters)
  File "/home/petrache/VENV/py3_venv/local/lib/python3.6/site-packages/netmiko/ssh_dispatcher.py", line 243, in ConnectHandler
    return ConnectionClass(*args, **kwargs)
  File "/home/petrache/VENV/py3_venv/local/lib/python3.6/site-packages/netmiko/base_connection.py", line 317, in __init__
    self._open()
  File "/home/petrache/VENV/py3_venv/local/lib/python3.6/site-packages/netmiko/base_connection.py", line 322, in _open
    self.establish_connection()
  File "/home/petrache/VENV/py3_venv/local/lib/python3.6/site-packages/netmiko/base_connection.py", line 869, in establish_connection
    self.remote_conn_pre.connect(**ssh_connect_params)
  File "/home/petrache/VENV/py3_venv/local/lib/python3.6/site-packages/paramiko/client.py", line 446, in connect
    passphrase,
  File "/home/petrache/VENV/py3_venv/local/lib/python3.6/site-packages/paramiko/client.py", line 765, in _auth
    raise SSHException("No authentication methods available")
paramiko.ssh_exception.SSHException: No authentication methods available

2019-10-18 05:14:44,283 - nornir.core.task -    ERROR -      start() - Host 'arista3': task 'netmiko_direct' failed with traceback:
Traceback (most recent call last):
  File "/home/petrache/VENV/py3_venv/local/lib/python3.6/site-packages/nornir/core/task.py", line 67, in start
    r = self.task(self, **self.params)
  File "exercise3.py", line 9, in netmiko_direct
    net_connect = task.host.get_connection("netmiko", task.nornir.config)
  File "/home/petrache/VENV/py3_venv/local/lib/python3.6/site-packages/nornir/core/inventory.py", line 302, in get_connection
    extras=conn.extras,
  File "/home/petrache/VENV/py3_venv/local/lib/python3.6/site-packages/nornir/core/inventory.py", line 352, in open_connection
    configuration=configuration,
  File "/home/petrache/VENV/py3_venv/local/lib/python3.6/site-packages/nornir/plugins/connections/netmiko.py", line 58, in open
    self.connection = ConnectHandler(**parameters)
  File "/home/petrache/VENV/py3_venv/local/lib/python3.6/site-packages/netmiko/ssh_dispatcher.py", line 243, in ConnectHandler
    return ConnectionClass(*args, **kwargs)
  File "/home/petrache/VENV/py3_venv/local/lib/python3.6/site-packages/netmiko/base_connection.py", line 317, in __init__
    self._open()
  File "/home/petrache/VENV/py3_venv/local/lib/python3.6/site-packages/netmiko/base_connection.py", line 322, in _open
    self.establish_connection()
  File "/home/petrache/VENV/py3_venv/local/lib/python3.6/site-packages/netmiko/base_connection.py", line 869, in establish_connection
    self.remote_conn_pre.connect(**ssh_connect_params)
  File "/home/petrache/VENV/py3_venv/local/lib/python3.6/site-packages/paramiko/client.py", line 446, in connect
    passphrase,
  File "/home/petrache/VENV/py3_venv/local/lib/python3.6/site-packages/paramiko/client.py", line 765, in _auth
    raise SSHException("No authentication methods available")
paramiko.ssh_exception.SSHException: No authentication methods available

2019-10-18 05:14:44,760 - nornir.core.task -    ERROR -      start() - Host 'arista4': task 'netmiko_direct' failed with traceback:
Traceback (most recent call last):
  File "/home/petrache/VENV/py3_venv/local/lib/python3.6/site-packages/nornir/core/task.py", line 67, in start
    r = self.task(self, **self.params)
  File "exercise3.py", line 9, in netmiko_direct
    net_connect = task.host.get_connection("netmiko", task.nornir.config)
  File "/home/petrache/VENV/py3_venv/local/lib/python3.6/site-packages/nornir/core/inventory.py", line 302, in get_connection
    extras=conn.extras,
  File "/home/petrache/VENV/py3_venv/local/lib/python3.6/site-packages/nornir/core/inventory.py", line 352, in open_connection
    configuration=configuration,
  File "/home/petrache/VENV/py3_venv/local/lib/python3.6/site-packages/nornir/plugins/connections/netmiko.py", line 58, in open
    self.connection = ConnectHandler(**parameters)
  File "/home/petrache/VENV/py3_venv/local/lib/python3.6/site-packages/netmiko/ssh_dispatcher.py", line 243, in ConnectHandler
    return ConnectionClass(*args, **kwargs)
  File "/home/petrache/VENV/py3_venv/local/lib/python3.6/site-packages/netmiko/base_connection.py", line 317, in __init__
    self._open()
  File "/home/petrache/VENV/py3_venv/local/lib/python3.6/site-packages/netmiko/base_connection.py", line 322, in _open
    self.establish_connection()
  File "/home/petrache/VENV/py3_venv/local/lib/python3.6/site-packages/netmiko/base_connection.py", line 869, in establish_connection
    self.remote_conn_pre.connect(**ssh_connect_params)
  File "/home/petrache/VENV/py3_venv/local/lib/python3.6/site-packages/paramiko/client.py", line 446, in connect
    passphrase,
  File "/home/petrache/VENV/py3_venv/local/lib/python3.6/site-packages/paramiko/client.py", line 765, in _auth
    raise SSHException("No authentication methods available")
paramiko.ssh_exception.SSHException: No authentication methods available

2019-10-18 05:14:45,189 - nornir.core.task -    ERROR -      start() - Host 'srx2': task 'netmiko_direct' failed with traceback:
Traceback (most recent call last):
  File "/home/petrache/VENV/py3_venv/local/lib/python3.6/site-packages/nornir/core/task.py", line 67, in start
    r = self.task(self, **self.params)
  File "exercise3.py", line 9, in netmiko_direct
    net_connect = task.host.get_connection("netmiko", task.nornir.config)
  File "/home/petrache/VENV/py3_venv/local/lib/python3.6/site-packages/nornir/core/inventory.py", line 302, in get_connection
    extras=conn.extras,
  File "/home/petrache/VENV/py3_venv/local/lib/python3.6/site-packages/nornir/core/inventory.py", line 352, in open_connection
    configuration=configuration,
  File "/home/petrache/VENV/py3_venv/local/lib/python3.6/site-packages/nornir/plugins/connections/netmiko.py", line 58, in open
    self.connection = ConnectHandler(**parameters)
  File "/home/petrache/VENV/py3_venv/local/lib/python3.6/site-packages/netmiko/ssh_dispatcher.py", line 243, in ConnectHandler
    return ConnectionClass(*args, **kwargs)
  File "/home/petrache/VENV/py3_venv/local/lib/python3.6/site-packages/netmiko/base_connection.py", line 317, in __init__
    self._open()
  File "/home/petrache/VENV/py3_venv/local/lib/python3.6/site-packages/netmiko/base_connection.py", line 322, in _open
    self.establish_connection()
  File "/home/petrache/VENV/py3_venv/local/lib/python3.6/site-packages/netmiko/base_connection.py", line 869, in establish_connection
    self.remote_conn_pre.connect(**ssh_connect_params)
  File "/home/petrache/VENV/py3_venv/local/lib/python3.6/site-packages/paramiko/client.py", line 446, in connect
    passphrase,
  File "/home/petrache/VENV/py3_venv/local/lib/python3.6/site-packages/paramiko/client.py", line 765, in _auth
    raise SSHException("No authentication methods available")
paramiko.ssh_exception.SSHException: No authentication methods available

2019-10-18 05:27:15,128 -  nornir.core -     INFO -        run() - Running task 'netmiko_direct' with args {} on 1 hosts
2019-10-18 05:28:44,606 -  nornir.core -     INFO -        run() - Running task 'netmiko_direct' with args {} on 1 hosts
2019-10-18 05:29:28,587 -  nornir.core -     INFO -        run() - Running task 'netmiko_direct' with args {} on 1 hosts
2019-10-18 05:30:43,613 -  nornir.core -     INFO -        run() - Running task 'netmiko_direct' with args {} on 1 hosts
2019-10-18 05:30:46,250 - nornir.core.task -    ERROR -      start() - Host 'cisco3': task 'netmiko_direct' failed with traceback:
Traceback (most recent call last):
  File "/home/petrache/VENV/py3_venv/local/lib/python3.6/site-packages/netmiko/base_connection.py", line 869, in establish_connection
    self.remote_conn_pre.connect(**ssh_connect_params)
  File "/home/petrache/VENV/py3_venv/local/lib/python3.6/site-packages/paramiko/client.py", line 446, in connect
    passphrase,
  File "/home/petrache/VENV/py3_venv/local/lib/python3.6/site-packages/paramiko/client.py", line 764, in _auth
    raise saved_exception
  File "/home/petrache/VENV/py3_venv/local/lib/python3.6/site-packages/paramiko/client.py", line 751, in _auth
    self._transport.auth_password(username, password)
  File "/home/petrache/VENV/py3_venv/local/lib/python3.6/site-packages/paramiko/transport.py", line 1509, in auth_password
    return self.auth_handler.wait_for_response(my_event)
  File "/home/petrache/VENV/py3_venv/local/lib/python3.6/site-packages/paramiko/auth_handler.py", line 236, in wait_for_response
    raise e
paramiko.ssh_exception.AuthenticationException: Authentication failed.

During handling of the above exception, another exception occurred:

Traceback (most recent call last):
  File "/home/petrache/VENV/py3_venv/local/lib/python3.6/site-packages/nornir/core/task.py", line 67, in start
    r = self.task(self, **self.params)
  File "exercise3.py", line 10, in netmiko_direct
    net_connect = task.host.get_connection("netmiko", task.nornir.config)
  File "/home/petrache/VENV/py3_venv/local/lib/python3.6/site-packages/nornir/core/inventory.py", line 302, in get_connection
    extras=conn.extras,
  File "/home/petrache/VENV/py3_venv/local/lib/python3.6/site-packages/nornir/core/inventory.py", line 352, in open_connection
    configuration=configuration,
  File "/home/petrache/VENV/py3_venv/local/lib/python3.6/site-packages/nornir/plugins/connections/netmiko.py", line 58, in open
    self.connection = ConnectHandler(**parameters)
  File "/home/petrache/VENV/py3_venv/local/lib/python3.6/site-packages/netmiko/ssh_dispatcher.py", line 243, in ConnectHandler
    return ConnectionClass(*args, **kwargs)
  File "/home/petrache/VENV/py3_venv/local/lib/python3.6/site-packages/netmiko/base_connection.py", line 317, in __init__
    self._open()
  File "/home/petrache/VENV/py3_venv/local/lib/python3.6/site-packages/netmiko/base_connection.py", line 322, in _open
    self.establish_connection()
  File "/home/petrache/VENV/py3_venv/local/lib/python3.6/site-packages/netmiko/base_connection.py", line 882, in establish_connection
    raise NetMikoAuthenticationException(msg)
netmiko.ssh_exception.NetMikoAuthenticationException: Authentication failure: unable to connect cisco_ios cisco3.lasthop.io:22
Authentication failed.

2019-10-18 05:31:38,866 -  nornir.core -     INFO -        run() - Running task 'netmiko_direct' with args {} on 1 hosts
2019-10-18 05:31:41,480 - nornir.core.task -    ERROR -      start() - Host 'cisco3': task 'netmiko_direct' failed with traceback:
Traceback (most recent call last):
  File "/home/petrache/VENV/py3_venv/local/lib/python3.6/site-packages/netmiko/base_connection.py", line 869, in establish_connection
    self.remote_conn_pre.connect(**ssh_connect_params)
  File "/home/petrache/VENV/py3_venv/local/lib/python3.6/site-packages/paramiko/client.py", line 446, in connect
    passphrase,
  File "/home/petrache/VENV/py3_venv/local/lib/python3.6/site-packages/paramiko/client.py", line 764, in _auth
    raise saved_exception
  File "/home/petrache/VENV/py3_venv/local/lib/python3.6/site-packages/paramiko/client.py", line 751, in _auth
    self._transport.auth_password(username, password)
  File "/home/petrache/VENV/py3_venv/local/lib/python3.6/site-packages/paramiko/transport.py", line 1509, in auth_password
    return self.auth_handler.wait_for_response(my_event)
  File "/home/petrache/VENV/py3_venv/local/lib/python3.6/site-packages/paramiko/auth_handler.py", line 236, in wait_for_response
    raise e
paramiko.ssh_exception.AuthenticationException: Authentication failed.

During handling of the above exception, another exception occurred:

Traceback (most recent call last):
  File "/home/petrache/VENV/py3_venv/local/lib/python3.6/site-packages/nornir/core/task.py", line 67, in start
    r = self.task(self, **self.params)
  File "exercise3.py", line 10, in netmiko_direct
    net_connect = task.host.get_connection("netmiko", task.nornir.config)
  File "/home/petrache/VENV/py3_venv/local/lib/python3.6/site-packages/nornir/core/inventory.py", line 302, in get_connection
    extras=conn.extras,
  File "/home/petrache/VENV/py3_venv/local/lib/python3.6/site-packages/nornir/core/inventory.py", line 352, in open_connection
    configuration=configuration,
  File "/home/petrache/VENV/py3_venv/local/lib/python3.6/site-packages/nornir/plugins/connections/netmiko.py", line 58, in open
    self.connection = ConnectHandler(**parameters)
  File "/home/petrache/VENV/py3_venv/local/lib/python3.6/site-packages/netmiko/ssh_dispatcher.py", line 243, in ConnectHandler
    return ConnectionClass(*args, **kwargs)
  File "/home/petrache/VENV/py3_venv/local/lib/python3.6/site-packages/netmiko/base_connection.py", line 317, in __init__
    self._open()
  File "/home/petrache/VENV/py3_venv/local/lib/python3.6/site-packages/netmiko/base_connection.py", line 322, in _open
    self.establish_connection()
  File "/home/petrache/VENV/py3_venv/local/lib/python3.6/site-packages/netmiko/base_connection.py", line 882, in establish_connection
    raise NetMikoAuthenticationException(msg)
netmiko.ssh_exception.NetMikoAuthenticationException: Authentication failure: unable to connect cisco_ios cisco3.lasthop.io:22
Authentication failed.

2019-10-18 05:32:51,938 -  nornir.core -     INFO -        run() - Running task 'netmiko_direct' with args {} on 1 hosts
2019-10-18 05:32:54,567 - nornir.core.task -    ERROR -      start() - Host 'cisco3': task 'netmiko_direct' failed with traceback:
Traceback (most recent call last):
  File "/home/petrache/VENV/py3_venv/local/lib/python3.6/site-packages/nornir/core/task.py", line 67, in start
    r = self.task(self, **self.params)
  File "exercise3.py", line 10, in netmiko_direct
    net_connect = task.host.get_connection("netmiko", task.nornir.config)
  File "/home/petrache/VENV/py3_venv/local/lib/python3.6/site-packages/nornir/core/inventory.py", line 302, in get_connection
    extras=conn.extras,
  File "/home/petrache/VENV/py3_venv/local/lib/python3.6/site-packages/nornir/core/inventory.py", line 352, in open_connection
    configuration=configuration,
  File "/home/petrache/VENV/py3_venv/local/lib/python3.6/site-packages/nornir/plugins/connections/netmiko.py", line 58, in open
    self.connection = ConnectHandler(**parameters)
  File "/home/petrache/VENV/py3_venv/local/lib/python3.6/site-packages/netmiko/ssh_dispatcher.py", line 243, in ConnectHandler
    return ConnectionClass(*args, **kwargs)
  File "/home/petrache/VENV/py3_venv/local/lib/python3.6/site-packages/netmiko/base_connection.py", line 317, in __init__
    self._open()
  File "/home/petrache/VENV/py3_venv/local/lib/python3.6/site-packages/netmiko/base_connection.py", line 322, in _open
    self.establish_connection()
  File "/home/petrache/VENV/py3_venv/local/lib/python3.6/site-packages/netmiko/base_connection.py", line 869, in establish_connection
    self.remote_conn_pre.connect(**ssh_connect_params)
  File "/home/petrache/VENV/py3_venv/local/lib/python3.6/site-packages/paramiko/client.py", line 446, in connect
    passphrase,
  File "/home/petrache/VENV/py3_venv/local/lib/python3.6/site-packages/paramiko/client.py", line 764, in _auth
    raise saved_exception
  File "/home/petrache/VENV/py3_venv/local/lib/python3.6/site-packages/paramiko/client.py", line 677, in _auth
    key_filename, pkey_class, passphrase
  File "/home/petrache/VENV/py3_venv/local/lib/python3.6/site-packages/paramiko/client.py", line 586, in _key_from_filepath
    key = klass.from_private_key_file(key_path, password)
  File "/home/petrache/VENV/py3_venv/local/lib/python3.6/site-packages/paramiko/pkey.py", line 206, in from_private_key_file
    key = cls(filename=filename, password=password)
  File "/home/petrache/VENV/py3_venv/local/lib/python3.6/site-packages/paramiko/ed25519key.py", line 78, in __init__
    data = self._read_private_key("OPENSSH", f)
  File "/home/petrache/VENV/py3_venv/local/lib/python3.6/site-packages/paramiko/pkey.py", line 289, in _read_private_key
    raise SSHException("not a valid " + tag + " private key file")
paramiko.ssh_exception.SSHException: not a valid OPENSSH private key file

2019-10-18 05:33:33,033 -  nornir.core -     INFO -        run() - Running task 'netmiko_direct' with args {} on 1 hosts
2019-10-18 05:33:33,447 - nornir.core.task -    ERROR -      start() - Host 'nxos1': task 'netmiko_direct' failed with traceback:
Traceback (most recent call last):
  File "/home/petrache/VENV/py3_venv/local/lib/python3.6/site-packages/nornir/core/task.py", line 67, in start
    r = self.task(self, **self.params)
  File "exercise3.py", line 10, in netmiko_direct
    net_connect = task.host.get_connection("netmiko", task.nornir.config)
  File "/home/petrache/VENV/py3_venv/local/lib/python3.6/site-packages/nornir/core/inventory.py", line 302, in get_connection
    extras=conn.extras,
  File "/home/petrache/VENV/py3_venv/local/lib/python3.6/site-packages/nornir/core/inventory.py", line 352, in open_connection
    configuration=configuration,
  File "/home/petrache/VENV/py3_venv/local/lib/python3.6/site-packages/nornir/plugins/connections/netmiko.py", line 58, in open
    self.connection = ConnectHandler(**parameters)
  File "/home/petrache/VENV/py3_venv/local/lib/python3.6/site-packages/netmiko/ssh_dispatcher.py", line 243, in ConnectHandler
    return ConnectionClass(*args, **kwargs)
  File "/home/petrache/VENV/py3_venv/local/lib/python3.6/site-packages/netmiko/base_connection.py", line 317, in __init__
    self._open()
  File "/home/petrache/VENV/py3_venv/local/lib/python3.6/site-packages/netmiko/base_connection.py", line 322, in _open
    self.establish_connection()
  File "/home/petrache/VENV/py3_venv/local/lib/python3.6/site-packages/netmiko/base_connection.py", line 869, in establish_connection
    self.remote_conn_pre.connect(**ssh_connect_params)
  File "/home/petrache/VENV/py3_venv/local/lib/python3.6/site-packages/paramiko/client.py", line 446, in connect
    passphrase,
  File "/home/petrache/VENV/py3_venv/local/lib/python3.6/site-packages/paramiko/client.py", line 765, in _auth
    raise SSHException("No authentication methods available")
paramiko.ssh_exception.SSHException: No authentication methods available

2019-10-18 05:42:55,380 -  nornir.core -     INFO -        run() - Running task 'netmiko_direct' with args {} on 1 hosts
2019-10-18 05:43:29,811 -  nornir.core -     INFO -        run() - Running task 'netmiko_direct' with args {} on 1 hosts
2019-10-18 05:43:46,061 -  nornir.core -     INFO -        run() - Running task 'netmiko_direct' with args {} on 1 hosts
2019-10-18 05:43:48,694 - nornir.core.task -    ERROR -      start() - Host 'cisco3': task 'netmiko_direct' failed with traceback:
Traceback (most recent call last):
  File "/home/petrache/VENV/py3_venv/local/lib/python3.6/site-packages/netmiko/base_connection.py", line 869, in establish_connection
    self.remote_conn_pre.connect(**ssh_connect_params)
  File "/home/petrache/VENV/py3_venv/local/lib/python3.6/site-packages/paramiko/client.py", line 446, in connect
    passphrase,
  File "/home/petrache/VENV/py3_venv/local/lib/python3.6/site-packages/paramiko/client.py", line 764, in _auth
    raise saved_exception
  File "/home/petrache/VENV/py3_venv/local/lib/python3.6/site-packages/paramiko/client.py", line 751, in _auth
    self._transport.auth_password(username, password)
  File "/home/petrache/VENV/py3_venv/local/lib/python3.6/site-packages/paramiko/transport.py", line 1509, in auth_password
    return self.auth_handler.wait_for_response(my_event)
  File "/home/petrache/VENV/py3_venv/local/lib/python3.6/site-packages/paramiko/auth_handler.py", line 236, in wait_for_response
    raise e
paramiko.ssh_exception.AuthenticationException: Authentication failed.

During handling of the above exception, another exception occurred:

Traceback (most recent call last):
  File "/home/petrache/VENV/py3_venv/local/lib/python3.6/site-packages/nornir/core/task.py", line 67, in start
    r = self.task(self, **self.params)
  File "exercise3.py", line 15, in netmiko_direct
    net_connect = task.host.get_connection("netmiko", task.nornir.config)
  File "/home/petrache/VENV/py3_venv/local/lib/python3.6/site-packages/nornir/core/inventory.py", line 302, in get_connection
    extras=conn.extras,
  File "/home/petrache/VENV/py3_venv/local/lib/python3.6/site-packages/nornir/core/inventory.py", line 352, in open_connection
    configuration=configuration,
  File "/home/petrache/VENV/py3_venv/local/lib/python3.6/site-packages/nornir/plugins/connections/netmiko.py", line 58, in open
    self.connection = ConnectHandler(**parameters)
  File "/home/petrache/VENV/py3_venv/local/lib/python3.6/site-packages/netmiko/ssh_dispatcher.py", line 243, in ConnectHandler
    return ConnectionClass(*args, **kwargs)
  File "/home/petrache/VENV/py3_venv/local/lib/python3.6/site-packages/netmiko/base_connection.py", line 317, in __init__
    self._open()
  File "/home/petrache/VENV/py3_venv/local/lib/python3.6/site-packages/netmiko/base_connection.py", line 322, in _open
    self.establish_connection()
  File "/home/petrache/VENV/py3_venv/local/lib/python3.6/site-packages/netmiko/base_connection.py", line 882, in establish_connection
    raise NetMikoAuthenticationException(msg)
netmiko.ssh_exception.NetMikoAuthenticationException: Authentication failure: unable to connect cisco_ios cisco3.lasthop.io:22
Authentication failed.

2019-10-18 05:44:05,696 -  nornir.core -     INFO -        run() - Running task 'netmiko_direct' with args {} on 1 hosts
2019-10-18 05:44:08,336 - nornir.core.task -    ERROR -      start() - Host 'cisco3': task 'netmiko_direct' failed with traceback:
Traceback (most recent call last):
  File "/home/petrache/VENV/py3_venv/local/lib/python3.6/site-packages/netmiko/base_connection.py", line 869, in establish_connection
    self.remote_conn_pre.connect(**ssh_connect_params)
  File "/home/petrache/VENV/py3_venv/local/lib/python3.6/site-packages/paramiko/client.py", line 446, in connect
    passphrase,
  File "/home/petrache/VENV/py3_venv/local/lib/python3.6/site-packages/paramiko/client.py", line 764, in _auth
    raise saved_exception
  File "/home/petrache/VENV/py3_venv/local/lib/python3.6/site-packages/paramiko/client.py", line 751, in _auth
    self._transport.auth_password(username, password)
  File "/home/petrache/VENV/py3_venv/local/lib/python3.6/site-packages/paramiko/transport.py", line 1509, in auth_password
    return self.auth_handler.wait_for_response(my_event)
  File "/home/petrache/VENV/py3_venv/local/lib/python3.6/site-packages/paramiko/auth_handler.py", line 236, in wait_for_response
    raise e
paramiko.ssh_exception.AuthenticationException: Authentication failed.

During handling of the above exception, another exception occurred:

Traceback (most recent call last):
  File "/home/petrache/VENV/py3_venv/local/lib/python3.6/site-packages/nornir/core/task.py", line 67, in start
    r = self.task(self, **self.params)
  File "exercise3.py", line 14, in netmiko_direct
    net_connect = task.host.get_connection("netmiko", task.nornir.config)
  File "/home/petrache/VENV/py3_venv/local/lib/python3.6/site-packages/nornir/core/inventory.py", line 302, in get_connection
    extras=conn.extras,
  File "/home/petrache/VENV/py3_venv/local/lib/python3.6/site-packages/nornir/core/inventory.py", line 352, in open_connection
    configuration=configuration,
  File "/home/petrache/VENV/py3_venv/local/lib/python3.6/site-packages/nornir/plugins/connections/netmiko.py", line 58, in open
    self.connection = ConnectHandler(**parameters)
  File "/home/petrache/VENV/py3_venv/local/lib/python3.6/site-packages/netmiko/ssh_dispatcher.py", line 243, in ConnectHandler
    return ConnectionClass(*args, **kwargs)
  File "/home/petrache/VENV/py3_venv/local/lib/python3.6/site-packages/netmiko/base_connection.py", line 317, in __init__
    self._open()
  File "/home/petrache/VENV/py3_venv/local/lib/python3.6/site-packages/netmiko/base_connection.py", line 322, in _open
    self.establish_connection()
  File "/home/petrache/VENV/py3_venv/local/lib/python3.6/site-packages/netmiko/base_connection.py", line 882, in establish_connection
    raise NetMikoAuthenticationException(msg)
netmiko.ssh_exception.NetMikoAuthenticationException: Authentication failure: unable to connect cisco_ios cisco3.lasthop.io:22
Authentication failed.

2019-10-18 05:48:03,220 -  nornir.core -     INFO -        run() - Running task 'netmiko_direct' with args {} on 9 hosts
2019-10-18 05:48:05,855 - nornir.core.task -    ERROR -      start() - Host 'cisco3': task 'netmiko_direct' failed with traceback:
Traceback (most recent call last):
  File "/home/petrache/VENV/py3_venv/local/lib/python3.6/site-packages/netmiko/base_connection.py", line 869, in establish_connection
    self.remote_conn_pre.connect(**ssh_connect_params)
  File "/home/petrache/VENV/py3_venv/local/lib/python3.6/site-packages/paramiko/client.py", line 446, in connect
    passphrase,
  File "/home/petrache/VENV/py3_venv/local/lib/python3.6/site-packages/paramiko/client.py", line 764, in _auth
    raise saved_exception
  File "/home/petrache/VENV/py3_venv/local/lib/python3.6/site-packages/paramiko/client.py", line 751, in _auth
    self._transport.auth_password(username, password)
  File "/home/petrache/VENV/py3_venv/local/lib/python3.6/site-packages/paramiko/transport.py", line 1509, in auth_password
    return self.auth_handler.wait_for_response(my_event)
  File "/home/petrache/VENV/py3_venv/local/lib/python3.6/site-packages/paramiko/auth_handler.py", line 236, in wait_for_response
    raise e
paramiko.ssh_exception.AuthenticationException: Authentication failed.

During handling of the above exception, another exception occurred:

Traceback (most recent call last):
  File "/home/petrache/VENV/py3_venv/local/lib/python3.6/site-packages/nornir/core/task.py", line 67, in start
    r = self.task(self, **self.params)
  File "exercise3.py", line 14, in netmiko_direct
    net_connect = task.host.get_connection("netmiko", task.nornir.config)
  File "/home/petrache/VENV/py3_venv/local/lib/python3.6/site-packages/nornir/core/inventory.py", line 302, in get_connection
    extras=conn.extras,
  File "/home/petrache/VENV/py3_venv/local/lib/python3.6/site-packages/nornir/core/inventory.py", line 352, in open_connection
    configuration=configuration,
  File "/home/petrache/VENV/py3_venv/local/lib/python3.6/site-packages/nornir/plugins/connections/netmiko.py", line 58, in open
    self.connection = ConnectHandler(**parameters)
  File "/home/petrache/VENV/py3_venv/local/lib/python3.6/site-packages/netmiko/ssh_dispatcher.py", line 243, in ConnectHandler
    return ConnectionClass(*args, **kwargs)
  File "/home/petrache/VENV/py3_venv/local/lib/python3.6/site-packages/netmiko/base_connection.py", line 317, in __init__
    self._open()
  File "/home/petrache/VENV/py3_venv/local/lib/python3.6/site-packages/netmiko/base_connection.py", line 322, in _open
    self.establish_connection()
  File "/home/petrache/VENV/py3_venv/local/lib/python3.6/site-packages/netmiko/base_connection.py", line 882, in establish_connection
    raise NetMikoAuthenticationException(msg)
netmiko.ssh_exception.NetMikoAuthenticationException: Authentication failure: unable to connect cisco_ios cisco3.lasthop.io:22
Authentication failed.

2019-10-18 05:48:08,481 - nornir.core.task -    ERROR -      start() - Host 'cisco4': task 'netmiko_direct' failed with traceback:
Traceback (most recent call last):
  File "/home/petrache/VENV/py3_venv/local/lib/python3.6/site-packages/netmiko/base_connection.py", line 869, in establish_connection
    self.remote_conn_pre.connect(**ssh_connect_params)
  File "/home/petrache/VENV/py3_venv/local/lib/python3.6/site-packages/paramiko/client.py", line 446, in connect
    passphrase,
  File "/home/petrache/VENV/py3_venv/local/lib/python3.6/site-packages/paramiko/client.py", line 764, in _auth
    raise saved_exception
  File "/home/petrache/VENV/py3_venv/local/lib/python3.6/site-packages/paramiko/client.py", line 751, in _auth
    self._transport.auth_password(username, password)
  File "/home/petrache/VENV/py3_venv/local/lib/python3.6/site-packages/paramiko/transport.py", line 1509, in auth_password
    return self.auth_handler.wait_for_response(my_event)
  File "/home/petrache/VENV/py3_venv/local/lib/python3.6/site-packages/paramiko/auth_handler.py", line 236, in wait_for_response
    raise e
paramiko.ssh_exception.AuthenticationException: Authentication failed.

During handling of the above exception, another exception occurred:

Traceback (most recent call last):
  File "/home/petrache/VENV/py3_venv/local/lib/python3.6/site-packages/nornir/core/task.py", line 67, in start
    r = self.task(self, **self.params)
  File "exercise3.py", line 14, in netmiko_direct
    net_connect = task.host.get_connection("netmiko", task.nornir.config)
  File "/home/petrache/VENV/py3_venv/local/lib/python3.6/site-packages/nornir/core/inventory.py", line 302, in get_connection
    extras=conn.extras,
  File "/home/petrache/VENV/py3_venv/local/lib/python3.6/site-packages/nornir/core/inventory.py", line 352, in open_connection
    configuration=configuration,
  File "/home/petrache/VENV/py3_venv/local/lib/python3.6/site-packages/nornir/plugins/connections/netmiko.py", line 58, in open
    self.connection = ConnectHandler(**parameters)
  File "/home/petrache/VENV/py3_venv/local/lib/python3.6/site-packages/netmiko/ssh_dispatcher.py", line 243, in ConnectHandler
    return ConnectionClass(*args, **kwargs)
  File "/home/petrache/VENV/py3_venv/local/lib/python3.6/site-packages/netmiko/base_connection.py", line 317, in __init__
    self._open()
  File "/home/petrache/VENV/py3_venv/local/lib/python3.6/site-packages/netmiko/base_connection.py", line 322, in _open
    self.establish_connection()
  File "/home/petrache/VENV/py3_venv/local/lib/python3.6/site-packages/netmiko/base_connection.py", line 882, in establish_connection
    raise NetMikoAuthenticationException(msg)
netmiko.ssh_exception.NetMikoAuthenticationException: Authentication failure: unable to connect cisco_ios cisco4.lasthop.io:22
Authentication failed.

2019-10-18 05:53:51,139 -  nornir.core -     INFO -        run() - Running task 'netmiko_direct' with args {} on 9 hosts
2019-10-18 05:54:30,100 -  nornir.core -     INFO -        run() - Running task 'netmiko_direct' with args {} on 1 hosts
2019-10-18 13:18:50,667 -  nornir.core -     INFO -        run() - Running task 'netmiko_direct' with args {} on 1 hosts
2019-10-18 13:18:51,070 - nornir.core.task -    ERROR -      start() - Host 'cisco3': task 'netmiko_direct' failed with traceback:
Traceback (most recent call last):
  File "/home/petrache/VENV/py3_venv/local/lib/python3.6/site-packages/nornir/core/task.py", line 67, in start
    r = self.task(self, **self.params)
  File "exercise3.py", line 10, in netmiko_direct
    net_connect = task.host.get_connection("netmiko", task.nornir.config)
  File "/home/petrache/VENV/py3_venv/local/lib/python3.6/site-packages/nornir/core/inventory.py", line 302, in get_connection
    extras=conn.extras,
  File "/home/petrache/VENV/py3_venv/local/lib/python3.6/site-packages/nornir/core/inventory.py", line 352, in open_connection
    configuration=configuration,
  File "/home/petrache/VENV/py3_venv/local/lib/python3.6/site-packages/nornir/plugins/connections/netmiko.py", line 58, in open
    self.connection = ConnectHandler(**parameters)
  File "/home/petrache/VENV/py3_venv/local/lib/python3.6/site-packages/netmiko/ssh_dispatcher.py", line 243, in ConnectHandler
    return ConnectionClass(*args, **kwargs)
  File "/home/petrache/VENV/py3_venv/local/lib/python3.6/site-packages/netmiko/base_connection.py", line 317, in __init__
    self._open()
  File "/home/petrache/VENV/py3_venv/local/lib/python3.6/site-packages/netmiko/base_connection.py", line 322, in _open
    self.establish_connection()
  File "/home/petrache/VENV/py3_venv/local/lib/python3.6/site-packages/netmiko/base_connection.py", line 869, in establish_connection
    self.remote_conn_pre.connect(**ssh_connect_params)
  File "/home/petrache/VENV/py3_venv/local/lib/python3.6/site-packages/paramiko/client.py", line 446, in connect
    passphrase,
  File "/home/petrache/VENV/py3_venv/local/lib/python3.6/site-packages/paramiko/client.py", line 765, in _auth
    raise SSHException("No authentication methods available")
paramiko.ssh_exception.SSHException: No authentication methods available

2019-10-18 13:22:49,510 -  nornir.core -     INFO -        run() - Running task 'netmiko_direct' with args {} on 1 hosts
2019-10-18 13:26:53,800 -  nornir.core -     INFO -        run() - Running task 'netmiko_direct' with args {} on 1 hosts
2019-10-18 13:27:34,875 -  nornir.core -     INFO -        run() - Running task 'netmiko_direct' with args {} on 9 hosts
