2019-08-21 05:43:21,681 -  nornir.core -     INFO -        run() - Running task 'napalm_get' with args {'getters': ['arp_table']} on 6 hosts
2019-08-21 05:44:04,949 -  nornir.core -     INFO -        run() - Running task 'napalm_get' with args {'getters': ['arp_table']} on 6 hosts
2019-08-21 05:44:33,741 -  nornir.core -     INFO -        run() - Running task 'napalm_get' with args {'getters': ['arp_table']} on 6 hosts
2019-08-21 05:45:32,912 -  nornir.core -     INFO -        run() - Running task 'napalm_get' with args {'getters': ['arp_table']} on 6 hosts
2019-08-21 05:45:56,278 -  nornir.core -     INFO -        run() - Running task 'napalm_get' with args {'getters': ['arp_table']} on 6 hosts
2019-08-21 05:47:11,060 -  nornir.core -     INFO -        run() - Running task 'napalm_get' with args {'getters': ['arp_table']} on 6 hosts
2019-08-21 05:47:40,644 -  nornir.core -     INFO -        run() - Running task 'napalm_get' with args {'getters': ['arp_table']} on 6 hosts
2019-08-21 05:48:28,490 -  nornir.core -     INFO -        run() - Running task 'napalm_get' with args {'getters': ['arp_table']} on 6 hosts
2019-08-21 05:49:27,041 -  nornir.core -     INFO -        run() - Running task 'napalm_get' with args {'getters': ['arp_table']} on 6 hosts
2019-08-21 05:53:12,718 -  nornir.core -     INFO -        run() - Running task 'napalm_get' with args {'getters': ['arp_table']} on 6 hosts
2019-08-21 05:53:18,163 -  nornir.core -     INFO -        run() - Running task 'napalm_get' with args {'getters': ['get_config']} on 6 hosts
2019-08-21 05:53:46,069 -  nornir.core -     INFO -        run() - Running task 'napalm_get' with args {'getters': ['arp_table']} on 6 hosts
2019-08-21 05:53:51,543 -  nornir.core -     INFO -        run() - Running task 'napalm_get' with args {'getters': ['get_config']} on 6 hosts
2019-08-21 05:55:02,589 -  nornir.core -     INFO -        run() - Running task 'napalm_get' with args {'getters': ['arp_table']} on 6 hosts
2019-08-21 05:55:08,021 -  nornir.core -     INFO -        run() - Running task 'napalm_get' with args {'getters': ['get_config']} on 6 hosts
2019-08-21 05:55:58,750 -  nornir.core -     INFO -        run() - Running task 'napalm_get' with args {'getters': ['arp_table']} on 6 hosts
2019-08-21 05:56:04,323 -  nornir.core -     INFO -        run() - Running task 'napalm_get' with args {'getters': ['get_config']} on 6 hosts
2019-08-21 05:56:59,126 -  nornir.core -     INFO -        run() - Running task 'napalm_get' with args {'getters': ['arp_table']} on 6 hosts
2019-08-21 05:57:04,447 -  nornir.core -     INFO -        run() - Running task 'napalm_get' with args {'getters': ['get_config']} on 6 hosts
2019-08-21 05:57:33,010 -  nornir.core -     INFO -        run() - Running task 'napalm_get' with args {'getters': ['arp_table']} on 6 hosts
2019-08-21 05:57:38,482 -  nornir.core -     INFO -        run() - Running task 'napalm_get' with args {'getters': ['get_config']} on 6 hosts
2019-08-21 05:59:35,688 -  nornir.core -     INFO -        run() - Running task 'napalm_get' with args {'getters': ['arp_table']} on 6 hosts
2019-08-21 05:59:41,113 -  nornir.core -     INFO -        run() - Running task 'napalm_get' with args {'getters': ['route_to']} on 6 hosts
2019-08-21 05:59:41,120 - nornir.core.task -    ERROR -      start() - Host 'cisco4': task 'napalm_get' failed with traceback:
Traceback (most recent call last):
  File "/home/petrache/VENV/py3_venv/local/lib/python3.6/site-packages/nornir/core/task.py", line 67, in start
    r = self.task(self, **self.params)
  File "/home/petrache/VENV/py3_venv/local/lib/python3.6/site-packages/nornir/plugins/tasks/networking/napalm_get.py", line 61, in napalm_get
    result[g] = method(**options)
  File "/home/petrache/VENV/py3_venv/src/napalm/napalm/base/base.py", line 1070, in get_route_to
    raise NotImplementedError
NotImplementedError

2019-08-21 05:59:41,120 - nornir.core.task -    ERROR -      start() - Host 'cisco3': task 'napalm_get' failed with traceback:
Traceback (most recent call last):
  File "/home/petrache/VENV/py3_venv/local/lib/python3.6/site-packages/nornir/core/task.py", line 67, in start
    r = self.task(self, **self.params)
  File "/home/petrache/VENV/py3_venv/local/lib/python3.6/site-packages/nornir/plugins/tasks/networking/napalm_get.py", line 61, in napalm_get
    result[g] = method(**options)
  File "/home/petrache/VENV/py3_venv/src/napalm/napalm/base/base.py", line 1070, in get_route_to
    raise NotImplementedError
NotImplementedError

2019-08-21 05:59:41,467 - nornir.core.task -    ERROR -      start() - Host 'arista3': task 'napalm_get' failed with traceback:
Traceback (most recent call last):
  File "/home/petrache/VENV/py3_venv/local/lib/python3.6/site-packages/netaddr/strategy/ipv4.py", line 125, in str_to_int
    return _struct.unpack('>I', _inet_pton(AF_INET, addr))[0]
OSError: illegal IP address string passed to inet_pton

During handling of the above exception, another exception occurred:

Traceback (most recent call last):
  File "/home/petrache/VENV/py3_venv/local/lib/python3.6/site-packages/netaddr/ip/__init__.py", line 311, in __init__
    self._value = self._module.str_to_int(addr, flags)
  File "/home/petrache/VENV/py3_venv/local/lib/python3.6/site-packages/netaddr/strategy/ipv4.py", line 129, in str_to_int
    raise AddrFormatError('%r is not a valid IPv4 address string!' % addr)
netaddr.core.AddrFormatError: '' is not a valid IPv4 address string!

During handling of the above exception, another exception occurred:

Traceback (most recent call last):
  File "/home/petrache/VENV/py3_venv/local/lib/python3.6/site-packages/netaddr/ip/__init__.py", line 791, in parse_ip_network
    ip = IPAddress(val1, module.version, flags=INET_PTON)
  File "/home/petrache/VENV/py3_venv/local/lib/python3.6/site-packages/netaddr/ip/__init__.py", line 314, in __init__
    % (addr, self._module.version))
netaddr.core.AddrFormatError: base address '' is not IPv4

During handling of the above exception, another exception occurred:

Traceback (most recent call last):
  File "/home/petrache/VENV/py3_venv/local/lib/python3.6/site-packages/netaddr/strategy/ipv4.py", line 265, in expand_partial_address
    tokens = ['%d' % int(addr)]
ValueError: invalid literal for int() with base 10: ''

During handling of the above exception, another exception occurred:

Traceback (most recent call last):
  File "/home/petrache/VENV/py3_venv/local/lib/python3.6/site-packages/netaddr/ip/__init__.py", line 928, in __init__
    implicit_prefix, flags)
  File "/home/petrache/VENV/py3_venv/local/lib/python3.6/site-packages/netaddr/ip/__init__.py", line 795, in parse_ip_network
    expanded_addr = _ipv4.expand_partial_address(val1)
  File "/home/petrache/VENV/py3_venv/local/lib/python3.6/site-packages/netaddr/strategy/ipv4.py", line 267, in expand_partial_address
    raise error
netaddr.core.AddrFormatError: invalid partial IPv4 address: ''!

During handling of the above exception, another exception occurred:

Traceback (most recent call last):
  File "/home/petrache/VENV/py3_venv/local/lib/python3.6/site-packages/nornir/core/task.py", line 67, in start
    r = self.task(self, **self.params)
  File "/home/petrache/VENV/py3_venv/local/lib/python3.6/site-packages/nornir/plugins/tasks/networking/napalm_get.py", line 61, in napalm_get
    result[g] = method(**options)
  File "/home/petrache/VENV/py3_venv/src/napalm/napalm/eos/eos.py", line 1159, in get_route_to
    if IPNetwork(destination).version == 6:
  File "/home/petrache/VENV/py3_venv/local/lib/python3.6/site-packages/netaddr/ip/__init__.py", line 938, in __init__
    raise AddrFormatError('invalid IPNetwork %s' % addr)
netaddr.core.AddrFormatError: invalid IPNetwork 

2019-08-21 05:59:41,500 - nornir.core.task -    ERROR -      start() - Host 'arista1': task 'napalm_get' failed with traceback:
Traceback (most recent call last):
  File "/home/petrache/VENV/py3_venv/local/lib/python3.6/site-packages/netaddr/strategy/ipv4.py", line 125, in str_to_int
    return _struct.unpack('>I', _inet_pton(AF_INET, addr))[0]
OSError: illegal IP address string passed to inet_pton

During handling of the above exception, another exception occurred:

Traceback (most recent call last):
  File "/home/petrache/VENV/py3_venv/local/lib/python3.6/site-packages/netaddr/ip/__init__.py", line 311, in __init__
    self._value = self._module.str_to_int(addr, flags)
  File "/home/petrache/VENV/py3_venv/local/lib/python3.6/site-packages/netaddr/strategy/ipv4.py", line 129, in str_to_int
    raise AddrFormatError('%r is not a valid IPv4 address string!' % addr)
netaddr.core.AddrFormatError: '' is not a valid IPv4 address string!

During handling of the above exception, another exception occurred:

Traceback (most recent call last):
  File "/home/petrache/VENV/py3_venv/local/lib/python3.6/site-packages/netaddr/ip/__init__.py", line 791, in parse_ip_network
    ip = IPAddress(val1, module.version, flags=INET_PTON)
  File "/home/petrache/VENV/py3_venv/local/lib/python3.6/site-packages/netaddr/ip/__init__.py", line 314, in __init__
    % (addr, self._module.version))
netaddr.core.AddrFormatError: base address '' is not IPv4

During handling of the above exception, another exception occurred:

Traceback (most recent call last):
  File "/home/petrache/VENV/py3_venv/local/lib/python3.6/site-packages/netaddr/strategy/ipv4.py", line 265, in expand_partial_address
    tokens = ['%d' % int(addr)]
ValueError: invalid literal for int() with base 10: ''

During handling of the above exception, another exception occurred:

Traceback (most recent call last):
  File "/home/petrache/VENV/py3_venv/local/lib/python3.6/site-packages/netaddr/ip/__init__.py", line 928, in __init__
    implicit_prefix, flags)
  File "/home/petrache/VENV/py3_venv/local/lib/python3.6/site-packages/netaddr/ip/__init__.py", line 795, in parse_ip_network
    expanded_addr = _ipv4.expand_partial_address(val1)
  File "/home/petrache/VENV/py3_venv/local/lib/python3.6/site-packages/netaddr/strategy/ipv4.py", line 267, in expand_partial_address
    raise error
netaddr.core.AddrFormatError: invalid partial IPv4 address: ''!

During handling of the above exception, another exception occurred:

Traceback (most recent call last):
  File "/home/petrache/VENV/py3_venv/local/lib/python3.6/site-packages/nornir/core/task.py", line 67, in start
    r = self.task(self, **self.params)
  File "/home/petrache/VENV/py3_venv/local/lib/python3.6/site-packages/nornir/plugins/tasks/networking/napalm_get.py", line 61, in napalm_get
    result[g] = method(**options)
  File "/home/petrache/VENV/py3_venv/src/napalm/napalm/eos/eos.py", line 1159, in get_route_to
    if IPNetwork(destination).version == 6:
  File "/home/petrache/VENV/py3_venv/local/lib/python3.6/site-packages/netaddr/ip/__init__.py", line 938, in __init__
    raise AddrFormatError('invalid IPNetwork %s' % addr)
netaddr.core.AddrFormatError: invalid IPNetwork 

2019-08-21 05:59:41,519 - nornir.core.task -    ERROR -      start() - Host 'arista4': task 'napalm_get' failed with traceback:
Traceback (most recent call last):
  File "/home/petrache/VENV/py3_venv/local/lib/python3.6/site-packages/netaddr/strategy/ipv4.py", line 125, in str_to_int
    return _struct.unpack('>I', _inet_pton(AF_INET, addr))[0]
OSError: illegal IP address string passed to inet_pton

During handling of the above exception, another exception occurred:

Traceback (most recent call last):
  File "/home/petrache/VENV/py3_venv/local/lib/python3.6/site-packages/netaddr/ip/__init__.py", line 311, in __init__
    self._value = self._module.str_to_int(addr, flags)
  File "/home/petrache/VENV/py3_venv/local/lib/python3.6/site-packages/netaddr/strategy/ipv4.py", line 129, in str_to_int
    raise AddrFormatError('%r is not a valid IPv4 address string!' % addr)
netaddr.core.AddrFormatError: '' is not a valid IPv4 address string!

During handling of the above exception, another exception occurred:

Traceback (most recent call last):
  File "/home/petrache/VENV/py3_venv/local/lib/python3.6/site-packages/netaddr/ip/__init__.py", line 791, in parse_ip_network
    ip = IPAddress(val1, module.version, flags=INET_PTON)
  File "/home/petrache/VENV/py3_venv/local/lib/python3.6/site-packages/netaddr/ip/__init__.py", line 314, in __init__
    % (addr, self._module.version))
netaddr.core.AddrFormatError: base address '' is not IPv4

During handling of the above exception, another exception occurred:

Traceback (most recent call last):
  File "/home/petrache/VENV/py3_venv/local/lib/python3.6/site-packages/netaddr/strategy/ipv4.py", line 265, in expand_partial_address
    tokens = ['%d' % int(addr)]
ValueError: invalid literal for int() with base 10: ''

During handling of the above exception, another exception occurred:

Traceback (most recent call last):
  File "/home/petrache/VENV/py3_venv/local/lib/python3.6/site-packages/netaddr/ip/__init__.py", line 928, in __init__
    implicit_prefix, flags)
  File "/home/petrache/VENV/py3_venv/local/lib/python3.6/site-packages/netaddr/ip/__init__.py", line 795, in parse_ip_network
    expanded_addr = _ipv4.expand_partial_address(val1)
  File "/home/petrache/VENV/py3_venv/local/lib/python3.6/site-packages/netaddr/strategy/ipv4.py", line 267, in expand_partial_address
    raise error
netaddr.core.AddrFormatError: invalid partial IPv4 address: ''!

During handling of the above exception, another exception occurred:

Traceback (most recent call last):
  File "/home/petrache/VENV/py3_venv/local/lib/python3.6/site-packages/nornir/core/task.py", line 67, in start
    r = self.task(self, **self.params)
  File "/home/petrache/VENV/py3_venv/local/lib/python3.6/site-packages/nornir/plugins/tasks/networking/napalm_get.py", line 61, in napalm_get
    result[g] = method(**options)
  File "/home/petrache/VENV/py3_venv/src/napalm/napalm/eos/eos.py", line 1159, in get_route_to
    if IPNetwork(destination).version == 6:
  File "/home/petrache/VENV/py3_venv/local/lib/python3.6/site-packages/netaddr/ip/__init__.py", line 938, in __init__
    raise AddrFormatError('invalid IPNetwork %s' % addr)
netaddr.core.AddrFormatError: invalid IPNetwork 

2019-08-21 05:59:41,584 - nornir.core.task -    ERROR -      start() - Host 'arista2': task 'napalm_get' failed with traceback:
Traceback (most recent call last):
  File "/home/petrache/VENV/py3_venv/local/lib/python3.6/site-packages/netaddr/strategy/ipv4.py", line 125, in str_to_int
    return _struct.unpack('>I', _inet_pton(AF_INET, addr))[0]
OSError: illegal IP address string passed to inet_pton

During handling of the above exception, another exception occurred:

Traceback (most recent call last):
  File "/home/petrache/VENV/py3_venv/local/lib/python3.6/site-packages/netaddr/ip/__init__.py", line 311, in __init__
    self._value = self._module.str_to_int(addr, flags)
  File "/home/petrache/VENV/py3_venv/local/lib/python3.6/site-packages/netaddr/strategy/ipv4.py", line 129, in str_to_int
    raise AddrFormatError('%r is not a valid IPv4 address string!' % addr)
netaddr.core.AddrFormatError: '' is not a valid IPv4 address string!

During handling of the above exception, another exception occurred:

Traceback (most recent call last):
  File "/home/petrache/VENV/py3_venv/local/lib/python3.6/site-packages/netaddr/ip/__init__.py", line 791, in parse_ip_network
    ip = IPAddress(val1, module.version, flags=INET_PTON)
  File "/home/petrache/VENV/py3_venv/local/lib/python3.6/site-packages/netaddr/ip/__init__.py", line 314, in __init__
    % (addr, self._module.version))
netaddr.core.AddrFormatError: base address '' is not IPv4

During handling of the above exception, another exception occurred:

Traceback (most recent call last):
  File "/home/petrache/VENV/py3_venv/local/lib/python3.6/site-packages/netaddr/strategy/ipv4.py", line 265, in expand_partial_address
    tokens = ['%d' % int(addr)]
ValueError: invalid literal for int() with base 10: ''

During handling of the above exception, another exception occurred:

Traceback (most recent call last):
  File "/home/petrache/VENV/py3_venv/local/lib/python3.6/site-packages/netaddr/ip/__init__.py", line 928, in __init__
    implicit_prefix, flags)
  File "/home/petrache/VENV/py3_venv/local/lib/python3.6/site-packages/netaddr/ip/__init__.py", line 795, in parse_ip_network
    expanded_addr = _ipv4.expand_partial_address(val1)
  File "/home/petrache/VENV/py3_venv/local/lib/python3.6/site-packages/netaddr/strategy/ipv4.py", line 267, in expand_partial_address
    raise error
netaddr.core.AddrFormatError: invalid partial IPv4 address: ''!

During handling of the above exception, another exception occurred:

Traceback (most recent call last):
  File "/home/petrache/VENV/py3_venv/local/lib/python3.6/site-packages/nornir/core/task.py", line 67, in start
    r = self.task(self, **self.params)
  File "/home/petrache/VENV/py3_venv/local/lib/python3.6/site-packages/nornir/plugins/tasks/networking/napalm_get.py", line 61, in napalm_get
    result[g] = method(**options)
  File "/home/petrache/VENV/py3_venv/src/napalm/napalm/eos/eos.py", line 1159, in get_route_to
    if IPNetwork(destination).version == 6:
  File "/home/petrache/VENV/py3_venv/local/lib/python3.6/site-packages/netaddr/ip/__init__.py", line 938, in __init__
    raise AddrFormatError('invalid IPNetwork %s' % addr)
netaddr.core.AddrFormatError: invalid IPNetwork 

2019-08-21 06:00:13,470 -  nornir.core -     INFO -        run() - Running task 'napalm_get' with args {'getters': ['arp_table']} on 6 hosts
2019-08-21 06:00:19,041 -  nornir.core -     INFO -        run() - Running task 'napalm_get' with args {'getters': ['route_to']} on 6 hosts
2019-08-21 06:00:19,045 - nornir.core.task -    ERROR -      start() - Host 'cisco3': task 'napalm_get' failed with traceback:
Traceback (most recent call last):
  File "/home/petrache/VENV/py3_venv/local/lib/python3.6/site-packages/nornir/core/task.py", line 67, in start
    r = self.task(self, **self.params)
  File "/home/petrache/VENV/py3_venv/local/lib/python3.6/site-packages/nornir/plugins/tasks/networking/napalm_get.py", line 61, in napalm_get
    result[g] = method(**options)
  File "/home/petrache/VENV/py3_venv/src/napalm/napalm/base/base.py", line 1070, in get_route_to
    raise NotImplementedError
NotImplementedError

2019-08-21 06:00:19,045 - nornir.core.task -    ERROR -      start() - Host 'cisco4': task 'napalm_get' failed with traceback:
Traceback (most recent call last):
  File "/home/petrache/VENV/py3_venv/local/lib/python3.6/site-packages/nornir/core/task.py", line 67, in start
    r = self.task(self, **self.params)
  File "/home/petrache/VENV/py3_venv/local/lib/python3.6/site-packages/nornir/plugins/tasks/networking/napalm_get.py", line 61, in napalm_get
    result[g] = method(**options)
  File "/home/petrache/VENV/py3_venv/src/napalm/napalm/base/base.py", line 1070, in get_route_to
    raise NotImplementedError
NotImplementedError

2019-08-21 06:00:19,439 - nornir.core.task -    ERROR -      start() - Host 'arista3': task 'napalm_get' failed with traceback:
Traceback (most recent call last):
  File "/home/petrache/VENV/py3_venv/local/lib/python3.6/site-packages/netaddr/strategy/ipv4.py", line 125, in str_to_int
    return _struct.unpack('>I', _inet_pton(AF_INET, addr))[0]
OSError: illegal IP address string passed to inet_pton

During handling of the above exception, another exception occurred:

Traceback (most recent call last):
  File "/home/petrache/VENV/py3_venv/local/lib/python3.6/site-packages/netaddr/ip/__init__.py", line 311, in __init__
    self._value = self._module.str_to_int(addr, flags)
  File "/home/petrache/VENV/py3_venv/local/lib/python3.6/site-packages/netaddr/strategy/ipv4.py", line 129, in str_to_int
    raise AddrFormatError('%r is not a valid IPv4 address string!' % addr)
netaddr.core.AddrFormatError: '' is not a valid IPv4 address string!

During handling of the above exception, another exception occurred:

Traceback (most recent call last):
  File "/home/petrache/VENV/py3_venv/local/lib/python3.6/site-packages/netaddr/ip/__init__.py", line 791, in parse_ip_network
    ip = IPAddress(val1, module.version, flags=INET_PTON)
  File "/home/petrache/VENV/py3_venv/local/lib/python3.6/site-packages/netaddr/ip/__init__.py", line 314, in __init__
    % (addr, self._module.version))
netaddr.core.AddrFormatError: base address '' is not IPv4

During handling of the above exception, another exception occurred:

Traceback (most recent call last):
  File "/home/petrache/VENV/py3_venv/local/lib/python3.6/site-packages/netaddr/strategy/ipv4.py", line 265, in expand_partial_address
    tokens = ['%d' % int(addr)]
ValueError: invalid literal for int() with base 10: ''

During handling of the above exception, another exception occurred:

Traceback (most recent call last):
  File "/home/petrache/VENV/py3_venv/local/lib/python3.6/site-packages/netaddr/ip/__init__.py", line 928, in __init__
    implicit_prefix, flags)
  File "/home/petrache/VENV/py3_venv/local/lib/python3.6/site-packages/netaddr/ip/__init__.py", line 795, in parse_ip_network
    expanded_addr = _ipv4.expand_partial_address(val1)
  File "/home/petrache/VENV/py3_venv/local/lib/python3.6/site-packages/netaddr/strategy/ipv4.py", line 267, in expand_partial_address
    raise error
netaddr.core.AddrFormatError: invalid partial IPv4 address: ''!

During handling of the above exception, another exception occurred:

Traceback (most recent call last):
  File "/home/petrache/VENV/py3_venv/local/lib/python3.6/site-packages/nornir/core/task.py", line 67, in start
    r = self.task(self, **self.params)
  File "/home/petrache/VENV/py3_venv/local/lib/python3.6/site-packages/nornir/plugins/tasks/networking/napalm_get.py", line 61, in napalm_get
    result[g] = method(**options)
  File "/home/petrache/VENV/py3_venv/src/napalm/napalm/eos/eos.py", line 1159, in get_route_to
    if IPNetwork(destination).version == 6:
  File "/home/petrache/VENV/py3_venv/local/lib/python3.6/site-packages/netaddr/ip/__init__.py", line 938, in __init__
    raise AddrFormatError('invalid IPNetwork %s' % addr)
netaddr.core.AddrFormatError: invalid IPNetwork 

2019-08-21 06:00:19,444 - nornir.core.task -    ERROR -      start() - Host 'arista1': task 'napalm_get' failed with traceback:
Traceback (most recent call last):
  File "/home/petrache/VENV/py3_venv/local/lib/python3.6/site-packages/netaddr/strategy/ipv4.py", line 125, in str_to_int
    return _struct.unpack('>I', _inet_pton(AF_INET, addr))[0]
OSError: illegal IP address string passed to inet_pton

During handling of the above exception, another exception occurred:

Traceback (most recent call last):
  File "/home/petrache/VENV/py3_venv/local/lib/python3.6/site-packages/netaddr/ip/__init__.py", line 311, in __init__
    self._value = self._module.str_to_int(addr, flags)
  File "/home/petrache/VENV/py3_venv/local/lib/python3.6/site-packages/netaddr/strategy/ipv4.py", line 129, in str_to_int
    raise AddrFormatError('%r is not a valid IPv4 address string!' % addr)
netaddr.core.AddrFormatError: '' is not a valid IPv4 address string!

During handling of the above exception, another exception occurred:

Traceback (most recent call last):
  File "/home/petrache/VENV/py3_venv/local/lib/python3.6/site-packages/netaddr/ip/__init__.py", line 791, in parse_ip_network
    ip = IPAddress(val1, module.version, flags=INET_PTON)
  File "/home/petrache/VENV/py3_venv/local/lib/python3.6/site-packages/netaddr/ip/__init__.py", line 314, in __init__
    % (addr, self._module.version))
netaddr.core.AddrFormatError: base address '' is not IPv4

During handling of the above exception, another exception occurred:

Traceback (most recent call last):
  File "/home/petrache/VENV/py3_venv/local/lib/python3.6/site-packages/netaddr/strategy/ipv4.py", line 265, in expand_partial_address
    tokens = ['%d' % int(addr)]
ValueError: invalid literal for int() with base 10: ''

During handling of the above exception, another exception occurred:

Traceback (most recent call last):
  File "/home/petrache/VENV/py3_venv/local/lib/python3.6/site-packages/netaddr/ip/__init__.py", line 928, in __init__
    implicit_prefix, flags)
  File "/home/petrache/VENV/py3_venv/local/lib/python3.6/site-packages/netaddr/ip/__init__.py", line 795, in parse_ip_network
    expanded_addr = _ipv4.expand_partial_address(val1)
  File "/home/petrache/VENV/py3_venv/local/lib/python3.6/site-packages/netaddr/strategy/ipv4.py", line 267, in expand_partial_address
    raise error
netaddr.core.AddrFormatError: invalid partial IPv4 address: ''!

During handling of the above exception, another exception occurred:

Traceback (most recent call last):
  File "/home/petrache/VENV/py3_venv/local/lib/python3.6/site-packages/nornir/core/task.py", line 67, in start
    r = self.task(self, **self.params)
  File "/home/petrache/VENV/py3_venv/local/lib/python3.6/site-packages/nornir/plugins/tasks/networking/napalm_get.py", line 61, in napalm_get
    result[g] = method(**options)
  File "/home/petrache/VENV/py3_venv/src/napalm/napalm/eos/eos.py", line 1159, in get_route_to
    if IPNetwork(destination).version == 6:
  File "/home/petrache/VENV/py3_venv/local/lib/python3.6/site-packages/netaddr/ip/__init__.py", line 938, in __init__
    raise AddrFormatError('invalid IPNetwork %s' % addr)
netaddr.core.AddrFormatError: invalid IPNetwork 

2019-08-21 06:00:19,448 - nornir.core.task -    ERROR -      start() - Host 'arista2': task 'napalm_get' failed with traceback:
Traceback (most recent call last):
  File "/home/petrache/VENV/py3_venv/local/lib/python3.6/site-packages/netaddr/strategy/ipv4.py", line 125, in str_to_int
    return _struct.unpack('>I', _inet_pton(AF_INET, addr))[0]
OSError: illegal IP address string passed to inet_pton

During handling of the above exception, another exception occurred:

Traceback (most recent call last):
  File "/home/petrache/VENV/py3_venv/local/lib/python3.6/site-packages/netaddr/ip/__init__.py", line 311, in __init__
    self._value = self._module.str_to_int(addr, flags)
  File "/home/petrache/VENV/py3_venv/local/lib/python3.6/site-packages/netaddr/strategy/ipv4.py", line 129, in str_to_int
    raise AddrFormatError('%r is not a valid IPv4 address string!' % addr)
netaddr.core.AddrFormatError: '' is not a valid IPv4 address string!

During handling of the above exception, another exception occurred:

Traceback (most recent call last):
  File "/home/petrache/VENV/py3_venv/local/lib/python3.6/site-packages/netaddr/ip/__init__.py", line 791, in parse_ip_network
    ip = IPAddress(val1, module.version, flags=INET_PTON)
  File "/home/petrache/VENV/py3_venv/local/lib/python3.6/site-packages/netaddr/ip/__init__.py", line 314, in __init__
    % (addr, self._module.version))
netaddr.core.AddrFormatError: base address '' is not IPv4

During handling of the above exception, another exception occurred:

Traceback (most recent call last):
  File "/home/petrache/VENV/py3_venv/local/lib/python3.6/site-packages/netaddr/strategy/ipv4.py", line 265, in expand_partial_address
    tokens = ['%d' % int(addr)]
ValueError: invalid literal for int() with base 10: ''

During handling of the above exception, another exception occurred:

Traceback (most recent call last):
  File "/home/petrache/VENV/py3_venv/local/lib/python3.6/site-packages/netaddr/ip/__init__.py", line 928, in __init__
    implicit_prefix, flags)
  File "/home/petrache/VENV/py3_venv/local/lib/python3.6/site-packages/netaddr/ip/__init__.py", line 795, in parse_ip_network
    expanded_addr = _ipv4.expand_partial_address(val1)
  File "/home/petrache/VENV/py3_venv/local/lib/python3.6/site-packages/netaddr/strategy/ipv4.py", line 267, in expand_partial_address
    raise error
netaddr.core.AddrFormatError: invalid partial IPv4 address: ''!

During handling of the above exception, another exception occurred:

Traceback (most recent call last):
  File "/home/petrache/VENV/py3_venv/local/lib/python3.6/site-packages/nornir/core/task.py", line 67, in start
    r = self.task(self, **self.params)
  File "/home/petrache/VENV/py3_venv/local/lib/python3.6/site-packages/nornir/plugins/tasks/networking/napalm_get.py", line 61, in napalm_get
    result[g] = method(**options)
  File "/home/petrache/VENV/py3_venv/src/napalm/napalm/eos/eos.py", line 1159, in get_route_to
    if IPNetwork(destination).version == 6:
  File "/home/petrache/VENV/py3_venv/local/lib/python3.6/site-packages/netaddr/ip/__init__.py", line 938, in __init__
    raise AddrFormatError('invalid IPNetwork %s' % addr)
netaddr.core.AddrFormatError: invalid IPNetwork 

2019-08-21 06:00:19,487 - nornir.core.task -    ERROR -      start() - Host 'arista4': task 'napalm_get' failed with traceback:
Traceback (most recent call last):
  File "/home/petrache/VENV/py3_venv/local/lib/python3.6/site-packages/netaddr/strategy/ipv4.py", line 125, in str_to_int
    return _struct.unpack('>I', _inet_pton(AF_INET, addr))[0]
OSError: illegal IP address string passed to inet_pton

During handling of the above exception, another exception occurred:

Traceback (most recent call last):
  File "/home/petrache/VENV/py3_venv/local/lib/python3.6/site-packages/netaddr/ip/__init__.py", line 311, in __init__
    self._value = self._module.str_to_int(addr, flags)
  File "/home/petrache/VENV/py3_venv/local/lib/python3.6/site-packages/netaddr/strategy/ipv4.py", line 129, in str_to_int
    raise AddrFormatError('%r is not a valid IPv4 address string!' % addr)
netaddr.core.AddrFormatError: '' is not a valid IPv4 address string!

During handling of the above exception, another exception occurred:

Traceback (most recent call last):
  File "/home/petrache/VENV/py3_venv/local/lib/python3.6/site-packages/netaddr/ip/__init__.py", line 791, in parse_ip_network
    ip = IPAddress(val1, module.version, flags=INET_PTON)
  File "/home/petrache/VENV/py3_venv/local/lib/python3.6/site-packages/netaddr/ip/__init__.py", line 314, in __init__
    % (addr, self._module.version))
netaddr.core.AddrFormatError: base address '' is not IPv4

During handling of the above exception, another exception occurred:

Traceback (most recent call last):
  File "/home/petrache/VENV/py3_venv/local/lib/python3.6/site-packages/netaddr/strategy/ipv4.py", line 265, in expand_partial_address
    tokens = ['%d' % int(addr)]
ValueError: invalid literal for int() with base 10: ''

During handling of the above exception, another exception occurred:

Traceback (most recent call last):
  File "/home/petrache/VENV/py3_venv/local/lib/python3.6/site-packages/netaddr/ip/__init__.py", line 928, in __init__
    implicit_prefix, flags)
  File "/home/petrache/VENV/py3_venv/local/lib/python3.6/site-packages/netaddr/ip/__init__.py", line 795, in parse_ip_network
    expanded_addr = _ipv4.expand_partial_address(val1)
  File "/home/petrache/VENV/py3_venv/local/lib/python3.6/site-packages/netaddr/strategy/ipv4.py", line 267, in expand_partial_address
    raise error
netaddr.core.AddrFormatError: invalid partial IPv4 address: ''!

During handling of the above exception, another exception occurred:

Traceback (most recent call last):
  File "/home/petrache/VENV/py3_venv/local/lib/python3.6/site-packages/nornir/core/task.py", line 67, in start
    r = self.task(self, **self.params)
  File "/home/petrache/VENV/py3_venv/local/lib/python3.6/site-packages/nornir/plugins/tasks/networking/napalm_get.py", line 61, in napalm_get
    result[g] = method(**options)
  File "/home/petrache/VENV/py3_venv/src/napalm/napalm/eos/eos.py", line 1159, in get_route_to
    if IPNetwork(destination).version == 6:
  File "/home/petrache/VENV/py3_venv/local/lib/python3.6/site-packages/netaddr/ip/__init__.py", line 938, in __init__
    raise AddrFormatError('invalid IPNetwork %s' % addr)
netaddr.core.AddrFormatError: invalid IPNetwork 

2019-08-21 07:56:14,546 -  nornir.core -     INFO -        run() - Running task 'napalm_get' with args {'getters': ['arp_table']} on 6 hosts
2019-08-21 07:56:20,090 -  nornir.core -     INFO -        run() - Running task 'napalm_get' with args {'getters': ['route_to']} on 6 hosts
2019-08-21 07:56:20,094 - nornir.core.task -    ERROR -      start() - Host 'cisco3': task 'napalm_get' failed with traceback:
Traceback (most recent call last):
  File "/home/petrache/VENV/py3_venv/local/lib/python3.6/site-packages/nornir/core/task.py", line 67, in start
    r = self.task(self, **self.params)
  File "/home/petrache/VENV/py3_venv/local/lib/python3.6/site-packages/nornir/plugins/tasks/networking/napalm_get.py", line 61, in napalm_get
    result[g] = method(**options)
  File "/home/petrache/VENV/py3_venv/src/napalm/napalm/base/base.py", line 1070, in get_route_to
    raise NotImplementedError
NotImplementedError

2019-08-21 07:56:20,094 - nornir.core.task -    ERROR -      start() - Host 'cisco4': task 'napalm_get' failed with traceback:
Traceback (most recent call last):
  File "/home/petrache/VENV/py3_venv/local/lib/python3.6/site-packages/nornir/core/task.py", line 67, in start
    r = self.task(self, **self.params)
  File "/home/petrache/VENV/py3_venv/local/lib/python3.6/site-packages/nornir/plugins/tasks/networking/napalm_get.py", line 61, in napalm_get
    result[g] = method(**options)
  File "/home/petrache/VENV/py3_venv/src/napalm/napalm/base/base.py", line 1070, in get_route_to
    raise NotImplementedError
NotImplementedError

2019-08-21 07:56:20,490 - nornir.core.task -    ERROR -      start() - Host 'arista2': task 'napalm_get' failed with traceback:
Traceback (most recent call last):
  File "/home/petrache/VENV/py3_venv/local/lib/python3.6/site-packages/netaddr/strategy/ipv4.py", line 125, in str_to_int
    return _struct.unpack('>I', _inet_pton(AF_INET, addr))[0]
OSError: illegal IP address string passed to inet_pton

During handling of the above exception, another exception occurred:

Traceback (most recent call last):
  File "/home/petrache/VENV/py3_venv/local/lib/python3.6/site-packages/netaddr/ip/__init__.py", line 311, in __init__
    self._value = self._module.str_to_int(addr, flags)
  File "/home/petrache/VENV/py3_venv/local/lib/python3.6/site-packages/netaddr/strategy/ipv4.py", line 129, in str_to_int
    raise AddrFormatError('%r is not a valid IPv4 address string!' % addr)
netaddr.core.AddrFormatError: '' is not a valid IPv4 address string!

During handling of the above exception, another exception occurred:

Traceback (most recent call last):
  File "/home/petrache/VENV/py3_venv/local/lib/python3.6/site-packages/netaddr/ip/__init__.py", line 791, in parse_ip_network
    ip = IPAddress(val1, module.version, flags=INET_PTON)
  File "/home/petrache/VENV/py3_venv/local/lib/python3.6/site-packages/netaddr/ip/__init__.py", line 314, in __init__
    % (addr, self._module.version))
netaddr.core.AddrFormatError: base address '' is not IPv4

During handling of the above exception, another exception occurred:

Traceback (most recent call last):
  File "/home/petrache/VENV/py3_venv/local/lib/python3.6/site-packages/netaddr/strategy/ipv4.py", line 265, in expand_partial_address
    tokens = ['%d' % int(addr)]
ValueError: invalid literal for int() with base 10: ''

During handling of the above exception, another exception occurred:

Traceback (most recent call last):
  File "/home/petrache/VENV/py3_venv/local/lib/python3.6/site-packages/netaddr/ip/__init__.py", line 928, in __init__
    implicit_prefix, flags)
  File "/home/petrache/VENV/py3_venv/local/lib/python3.6/site-packages/netaddr/ip/__init__.py", line 795, in parse_ip_network
    expanded_addr = _ipv4.expand_partial_address(val1)
  File "/home/petrache/VENV/py3_venv/local/lib/python3.6/site-packages/netaddr/strategy/ipv4.py", line 267, in expand_partial_address
    raise error
netaddr.core.AddrFormatError: invalid partial IPv4 address: ''!

During handling of the above exception, another exception occurred:

Traceback (most recent call last):
  File "/home/petrache/VENV/py3_venv/local/lib/python3.6/site-packages/nornir/core/task.py", line 67, in start
    r = self.task(self, **self.params)
  File "/home/petrache/VENV/py3_venv/local/lib/python3.6/site-packages/nornir/plugins/tasks/networking/napalm_get.py", line 61, in napalm_get
    result[g] = method(**options)
  File "/home/petrache/VENV/py3_venv/src/napalm/napalm/eos/eos.py", line 1159, in get_route_to
    if IPNetwork(destination).version == 6:
  File "/home/petrache/VENV/py3_venv/local/lib/python3.6/site-packages/netaddr/ip/__init__.py", line 938, in __init__
    raise AddrFormatError('invalid IPNetwork %s' % addr)
netaddr.core.AddrFormatError: invalid IPNetwork 

2019-08-21 07:56:20,491 - nornir.core.task -    ERROR -      start() - Host 'arista1': task 'napalm_get' failed with traceback:
Traceback (most recent call last):
  File "/home/petrache/VENV/py3_venv/local/lib/python3.6/site-packages/netaddr/strategy/ipv4.py", line 125, in str_to_int
    return _struct.unpack('>I', _inet_pton(AF_INET, addr))[0]
OSError: illegal IP address string passed to inet_pton

During handling of the above exception, another exception occurred:

Traceback (most recent call last):
  File "/home/petrache/VENV/py3_venv/local/lib/python3.6/site-packages/netaddr/ip/__init__.py", line 311, in __init__
    self._value = self._module.str_to_int(addr, flags)
  File "/home/petrache/VENV/py3_venv/local/lib/python3.6/site-packages/netaddr/strategy/ipv4.py", line 129, in str_to_int
    raise AddrFormatError('%r is not a valid IPv4 address string!' % addr)
netaddr.core.AddrFormatError: '' is not a valid IPv4 address string!

During handling of the above exception, another exception occurred:

Traceback (most recent call last):
  File "/home/petrache/VENV/py3_venv/local/lib/python3.6/site-packages/netaddr/ip/__init__.py", line 791, in parse_ip_network
    ip = IPAddress(val1, module.version, flags=INET_PTON)
  File "/home/petrache/VENV/py3_venv/local/lib/python3.6/site-packages/netaddr/ip/__init__.py", line 314, in __init__
    % (addr, self._module.version))
netaddr.core.AddrFormatError: base address '' is not IPv4

During handling of the above exception, another exception occurred:

Traceback (most recent call last):
  File "/home/petrache/VENV/py3_venv/local/lib/python3.6/site-packages/netaddr/strategy/ipv4.py", line 265, in expand_partial_address
    tokens = ['%d' % int(addr)]
ValueError: invalid literal for int() with base 10: ''

During handling of the above exception, another exception occurred:

Traceback (most recent call last):
  File "/home/petrache/VENV/py3_venv/local/lib/python3.6/site-packages/netaddr/ip/__init__.py", line 928, in __init__
    implicit_prefix, flags)
  File "/home/petrache/VENV/py3_venv/local/lib/python3.6/site-packages/netaddr/ip/__init__.py", line 795, in parse_ip_network
    expanded_addr = _ipv4.expand_partial_address(val1)
  File "/home/petrache/VENV/py3_venv/local/lib/python3.6/site-packages/netaddr/strategy/ipv4.py", line 267, in expand_partial_address
    raise error
netaddr.core.AddrFormatError: invalid partial IPv4 address: ''!

During handling of the above exception, another exception occurred:

Traceback (most recent call last):
  File "/home/petrache/VENV/py3_venv/local/lib/python3.6/site-packages/nornir/core/task.py", line 67, in start
    r = self.task(self, **self.params)
  File "/home/petrache/VENV/py3_venv/local/lib/python3.6/site-packages/nornir/plugins/tasks/networking/napalm_get.py", line 61, in napalm_get
    result[g] = method(**options)
  File "/home/petrache/VENV/py3_venv/src/napalm/napalm/eos/eos.py", line 1159, in get_route_to
    if IPNetwork(destination).version == 6:
  File "/home/petrache/VENV/py3_venv/local/lib/python3.6/site-packages/netaddr/ip/__init__.py", line 938, in __init__
    raise AddrFormatError('invalid IPNetwork %s' % addr)
netaddr.core.AddrFormatError: invalid IPNetwork 

2019-08-21 07:56:20,503 - nornir.core.task -    ERROR -      start() - Host 'arista4': task 'napalm_get' failed with traceback:
Traceback (most recent call last):
  File "/home/petrache/VENV/py3_venv/local/lib/python3.6/site-packages/netaddr/strategy/ipv4.py", line 125, in str_to_int
    return _struct.unpack('>I', _inet_pton(AF_INET, addr))[0]
OSError: illegal IP address string passed to inet_pton

During handling of the above exception, another exception occurred:

Traceback (most recent call last):
  File "/home/petrache/VENV/py3_venv/local/lib/python3.6/site-packages/netaddr/ip/__init__.py", line 311, in __init__
    self._value = self._module.str_to_int(addr, flags)
  File "/home/petrache/VENV/py3_venv/local/lib/python3.6/site-packages/netaddr/strategy/ipv4.py", line 129, in str_to_int
    raise AddrFormatError('%r is not a valid IPv4 address string!' % addr)
netaddr.core.AddrFormatError: '' is not a valid IPv4 address string!

During handling of the above exception, another exception occurred:

Traceback (most recent call last):
  File "/home/petrache/VENV/py3_venv/local/lib/python3.6/site-packages/netaddr/ip/__init__.py", line 791, in parse_ip_network
    ip = IPAddress(val1, module.version, flags=INET_PTON)
  File "/home/petrache/VENV/py3_venv/local/lib/python3.6/site-packages/netaddr/ip/__init__.py", line 314, in __init__
    % (addr, self._module.version))
netaddr.core.AddrFormatError: base address '' is not IPv4

During handling of the above exception, another exception occurred:

Traceback (most recent call last):
  File "/home/petrache/VENV/py3_venv/local/lib/python3.6/site-packages/netaddr/strategy/ipv4.py", line 265, in expand_partial_address
    tokens = ['%d' % int(addr)]
ValueError: invalid literal for int() with base 10: ''

During handling of the above exception, another exception occurred:

Traceback (most recent call last):
  File "/home/petrache/VENV/py3_venv/local/lib/python3.6/site-packages/netaddr/ip/__init__.py", line 928, in __init__
    implicit_prefix, flags)
  File "/home/petrache/VENV/py3_venv/local/lib/python3.6/site-packages/netaddr/ip/__init__.py", line 795, in parse_ip_network
    expanded_addr = _ipv4.expand_partial_address(val1)
  File "/home/petrache/VENV/py3_venv/local/lib/python3.6/site-packages/netaddr/strategy/ipv4.py", line 267, in expand_partial_address
    raise error
netaddr.core.AddrFormatError: invalid partial IPv4 address: ''!

During handling of the above exception, another exception occurred:

Traceback (most recent call last):
  File "/home/petrache/VENV/py3_venv/local/lib/python3.6/site-packages/nornir/core/task.py", line 67, in start
    r = self.task(self, **self.params)
  File "/home/petrache/VENV/py3_venv/local/lib/python3.6/site-packages/nornir/plugins/tasks/networking/napalm_get.py", line 61, in napalm_get
    result[g] = method(**options)
  File "/home/petrache/VENV/py3_venv/src/napalm/napalm/eos/eos.py", line 1159, in get_route_to
    if IPNetwork(destination).version == 6:
  File "/home/petrache/VENV/py3_venv/local/lib/python3.6/site-packages/netaddr/ip/__init__.py", line 938, in __init__
    raise AddrFormatError('invalid IPNetwork %s' % addr)
netaddr.core.AddrFormatError: invalid IPNetwork 

2019-08-21 07:56:20,517 - nornir.core.task -    ERROR -      start() - Host 'arista3': task 'napalm_get' failed with traceback:
Traceback (most recent call last):
  File "/home/petrache/VENV/py3_venv/local/lib/python3.6/site-packages/netaddr/strategy/ipv4.py", line 125, in str_to_int
    return _struct.unpack('>I', _inet_pton(AF_INET, addr))[0]
OSError: illegal IP address string passed to inet_pton

During handling of the above exception, another exception occurred:

Traceback (most recent call last):
  File "/home/petrache/VENV/py3_venv/local/lib/python3.6/site-packages/netaddr/ip/__init__.py", line 311, in __init__
    self._value = self._module.str_to_int(addr, flags)
  File "/home/petrache/VENV/py3_venv/local/lib/python3.6/site-packages/netaddr/strategy/ipv4.py", line 129, in str_to_int
    raise AddrFormatError('%r is not a valid IPv4 address string!' % addr)
netaddr.core.AddrFormatError: '' is not a valid IPv4 address string!

During handling of the above exception, another exception occurred:

Traceback (most recent call last):
  File "/home/petrache/VENV/py3_venv/local/lib/python3.6/site-packages/netaddr/ip/__init__.py", line 791, in parse_ip_network
    ip = IPAddress(val1, module.version, flags=INET_PTON)
  File "/home/petrache/VENV/py3_venv/local/lib/python3.6/site-packages/netaddr/ip/__init__.py", line 314, in __init__
    % (addr, self._module.version))
netaddr.core.AddrFormatError: base address '' is not IPv4

During handling of the above exception, another exception occurred:

Traceback (most recent call last):
  File "/home/petrache/VENV/py3_venv/local/lib/python3.6/site-packages/netaddr/strategy/ipv4.py", line 265, in expand_partial_address
    tokens = ['%d' % int(addr)]
ValueError: invalid literal for int() with base 10: ''

During handling of the above exception, another exception occurred:

Traceback (most recent call last):
  File "/home/petrache/VENV/py3_venv/local/lib/python3.6/site-packages/netaddr/ip/__init__.py", line 928, in __init__
    implicit_prefix, flags)
  File "/home/petrache/VENV/py3_venv/local/lib/python3.6/site-packages/netaddr/ip/__init__.py", line 795, in parse_ip_network
    expanded_addr = _ipv4.expand_partial_address(val1)
  File "/home/petrache/VENV/py3_venv/local/lib/python3.6/site-packages/netaddr/strategy/ipv4.py", line 267, in expand_partial_address
    raise error
netaddr.core.AddrFormatError: invalid partial IPv4 address: ''!

During handling of the above exception, another exception occurred:

Traceback (most recent call last):
  File "/home/petrache/VENV/py3_venv/local/lib/python3.6/site-packages/nornir/core/task.py", line 67, in start
    r = self.task(self, **self.params)
  File "/home/petrache/VENV/py3_venv/local/lib/python3.6/site-packages/nornir/plugins/tasks/networking/napalm_get.py", line 61, in napalm_get
    result[g] = method(**options)
  File "/home/petrache/VENV/py3_venv/src/napalm/napalm/eos/eos.py", line 1159, in get_route_to
    if IPNetwork(destination).version == 6:
  File "/home/petrache/VENV/py3_venv/local/lib/python3.6/site-packages/netaddr/ip/__init__.py", line 938, in __init__
    raise AddrFormatError('invalid IPNetwork %s' % addr)
netaddr.core.AddrFormatError: invalid IPNetwork 

2019-08-21 07:56:39,729 -  nornir.core -     INFO -        run() - Running task 'napalm_get' with args {'getters': ['arp_table']} on 6 hosts
2019-08-21 07:56:45,200 -  nornir.core -     INFO -        run() - Running task 'napalm_get' with args {'getters': ['route_to']} on 6 hosts
2019-08-21 07:56:45,204 - nornir.core.task -    ERROR -      start() - Host 'cisco3': task 'napalm_get' failed with traceback:
Traceback (most recent call last):
  File "/home/petrache/VENV/py3_venv/local/lib/python3.6/site-packages/nornir/core/task.py", line 67, in start
    r = self.task(self, **self.params)
  File "/home/petrache/VENV/py3_venv/local/lib/python3.6/site-packages/nornir/plugins/tasks/networking/napalm_get.py", line 61, in napalm_get
    result[g] = method(**options)
  File "/home/petrache/VENV/py3_venv/src/napalm/napalm/base/base.py", line 1070, in get_route_to
    raise NotImplementedError
NotImplementedError

2019-08-21 07:56:45,204 - nornir.core.task -    ERROR -      start() - Host 'cisco4': task 'napalm_get' failed with traceback:
Traceback (most recent call last):
  File "/home/petrache/VENV/py3_venv/local/lib/python3.6/site-packages/nornir/core/task.py", line 67, in start
    r = self.task(self, **self.params)
  File "/home/petrache/VENV/py3_venv/local/lib/python3.6/site-packages/nornir/plugins/tasks/networking/napalm_get.py", line 61, in napalm_get
    result[g] = method(**options)
  File "/home/petrache/VENV/py3_venv/src/napalm/napalm/base/base.py", line 1070, in get_route_to
    raise NotImplementedError
NotImplementedError

2019-08-21 07:56:45,608 - nornir.core.task -    ERROR -      start() - Host 'arista1': task 'napalm_get' failed with traceback:
Traceback (most recent call last):
  File "/home/petrache/VENV/py3_venv/local/lib/python3.6/site-packages/netaddr/strategy/ipv4.py", line 125, in str_to_int
    return _struct.unpack('>I', _inet_pton(AF_INET, addr))[0]
OSError: illegal IP address string passed to inet_pton

During handling of the above exception, another exception occurred:

Traceback (most recent call last):
  File "/home/petrache/VENV/py3_venv/local/lib/python3.6/site-packages/netaddr/ip/__init__.py", line 311, in __init__
    self._value = self._module.str_to_int(addr, flags)
  File "/home/petrache/VENV/py3_venv/local/lib/python3.6/site-packages/netaddr/strategy/ipv4.py", line 129, in str_to_int
    raise AddrFormatError('%r is not a valid IPv4 address string!' % addr)
netaddr.core.AddrFormatError: '' is not a valid IPv4 address string!

During handling of the above exception, another exception occurred:

Traceback (most recent call last):
  File "/home/petrache/VENV/py3_venv/local/lib/python3.6/site-packages/netaddr/ip/__init__.py", line 791, in parse_ip_network
    ip = IPAddress(val1, module.version, flags=INET_PTON)
  File "/home/petrache/VENV/py3_venv/local/lib/python3.6/site-packages/netaddr/ip/__init__.py", line 314, in __init__
    % (addr, self._module.version))
netaddr.core.AddrFormatError: base address '' is not IPv4

During handling of the above exception, another exception occurred:

Traceback (most recent call last):
  File "/home/petrache/VENV/py3_venv/local/lib/python3.6/site-packages/netaddr/strategy/ipv4.py", line 265, in expand_partial_address
    tokens = ['%d' % int(addr)]
ValueError: invalid literal for int() with base 10: ''

During handling of the above exception, another exception occurred:

Traceback (most recent call last):
  File "/home/petrache/VENV/py3_venv/local/lib/python3.6/site-packages/netaddr/ip/__init__.py", line 928, in __init__
    implicit_prefix, flags)
  File "/home/petrache/VENV/py3_venv/local/lib/python3.6/site-packages/netaddr/ip/__init__.py", line 795, in parse_ip_network
    expanded_addr = _ipv4.expand_partial_address(val1)
  File "/home/petrache/VENV/py3_venv/local/lib/python3.6/site-packages/netaddr/strategy/ipv4.py", line 267, in expand_partial_address
    raise error
netaddr.core.AddrFormatError: invalid partial IPv4 address: ''!

During handling of the above exception, another exception occurred:

Traceback (most recent call last):
  File "/home/petrache/VENV/py3_venv/local/lib/python3.6/site-packages/nornir/core/task.py", line 67, in start
    r = self.task(self, **self.params)
  File "/home/petrache/VENV/py3_venv/local/lib/python3.6/site-packages/nornir/plugins/tasks/networking/napalm_get.py", line 61, in napalm_get
    result[g] = method(**options)
  File "/home/petrache/VENV/py3_venv/src/napalm/napalm/eos/eos.py", line 1159, in get_route_to
    if IPNetwork(destination).version == 6:
  File "/home/petrache/VENV/py3_venv/local/lib/python3.6/site-packages/netaddr/ip/__init__.py", line 938, in __init__
    raise AddrFormatError('invalid IPNetwork %s' % addr)
netaddr.core.AddrFormatError: invalid IPNetwork 

2019-08-21 07:56:45,608 - nornir.core.task -    ERROR -      start() - Host 'arista3': task 'napalm_get' failed with traceback:
Traceback (most recent call last):
  File "/home/petrache/VENV/py3_venv/local/lib/python3.6/site-packages/netaddr/strategy/ipv4.py", line 125, in str_to_int
    return _struct.unpack('>I', _inet_pton(AF_INET, addr))[0]
OSError: illegal IP address string passed to inet_pton

During handling of the above exception, another exception occurred:

Traceback (most recent call last):
  File "/home/petrache/VENV/py3_venv/local/lib/python3.6/site-packages/netaddr/ip/__init__.py", line 311, in __init__
    self._value = self._module.str_to_int(addr, flags)
  File "/home/petrache/VENV/py3_venv/local/lib/python3.6/site-packages/netaddr/strategy/ipv4.py", line 129, in str_to_int
    raise AddrFormatError('%r is not a valid IPv4 address string!' % addr)
netaddr.core.AddrFormatError: '' is not a valid IPv4 address string!

During handling of the above exception, another exception occurred:

Traceback (most recent call last):
  File "/home/petrache/VENV/py3_venv/local/lib/python3.6/site-packages/netaddr/ip/__init__.py", line 791, in parse_ip_network
    ip = IPAddress(val1, module.version, flags=INET_PTON)
  File "/home/petrache/VENV/py3_venv/local/lib/python3.6/site-packages/netaddr/ip/__init__.py", line 314, in __init__
    % (addr, self._module.version))
netaddr.core.AddrFormatError: base address '' is not IPv4

During handling of the above exception, another exception occurred:

Traceback (most recent call last):
  File "/home/petrache/VENV/py3_venv/local/lib/python3.6/site-packages/netaddr/strategy/ipv4.py", line 265, in expand_partial_address
    tokens = ['%d' % int(addr)]
ValueError: invalid literal for int() with base 10: ''

During handling of the above exception, another exception occurred:

Traceback (most recent call last):
  File "/home/petrache/VENV/py3_venv/local/lib/python3.6/site-packages/netaddr/ip/__init__.py", line 928, in __init__
    implicit_prefix, flags)
  File "/home/petrache/VENV/py3_venv/local/lib/python3.6/site-packages/netaddr/ip/__init__.py", line 795, in parse_ip_network
    expanded_addr = _ipv4.expand_partial_address(val1)
  File "/home/petrache/VENV/py3_venv/local/lib/python3.6/site-packages/netaddr/strategy/ipv4.py", line 267, in expand_partial_address
    raise error
netaddr.core.AddrFormatError: invalid partial IPv4 address: ''!

During handling of the above exception, another exception occurred:

Traceback (most recent call last):
  File "/home/petrache/VENV/py3_venv/local/lib/python3.6/site-packages/nornir/core/task.py", line 67, in start
    r = self.task(self, **self.params)
  File "/home/petrache/VENV/py3_venv/local/lib/python3.6/site-packages/nornir/plugins/tasks/networking/napalm_get.py", line 61, in napalm_get
    result[g] = method(**options)
  File "/home/petrache/VENV/py3_venv/src/napalm/napalm/eos/eos.py", line 1159, in get_route_to
    if IPNetwork(destination).version == 6:
  File "/home/petrache/VENV/py3_venv/local/lib/python3.6/site-packages/netaddr/ip/__init__.py", line 938, in __init__
    raise AddrFormatError('invalid IPNetwork %s' % addr)
netaddr.core.AddrFormatError: invalid IPNetwork 

2019-08-21 07:56:45,609 - nornir.core.task -    ERROR -      start() - Host 'arista2': task 'napalm_get' failed with traceback:
Traceback (most recent call last):
  File "/home/petrache/VENV/py3_venv/local/lib/python3.6/site-packages/netaddr/strategy/ipv4.py", line 125, in str_to_int
    return _struct.unpack('>I', _inet_pton(AF_INET, addr))[0]
OSError: illegal IP address string passed to inet_pton

During handling of the above exception, another exception occurred:

Traceback (most recent call last):
  File "/home/petrache/VENV/py3_venv/local/lib/python3.6/site-packages/netaddr/ip/__init__.py", line 311, in __init__
    self._value = self._module.str_to_int(addr, flags)
  File "/home/petrache/VENV/py3_venv/local/lib/python3.6/site-packages/netaddr/strategy/ipv4.py", line 129, in str_to_int
    raise AddrFormatError('%r is not a valid IPv4 address string!' % addr)
netaddr.core.AddrFormatError: '' is not a valid IPv4 address string!

During handling of the above exception, another exception occurred:

Traceback (most recent call last):
  File "/home/petrache/VENV/py3_venv/local/lib/python3.6/site-packages/netaddr/ip/__init__.py", line 791, in parse_ip_network
    ip = IPAddress(val1, module.version, flags=INET_PTON)
  File "/home/petrache/VENV/py3_venv/local/lib/python3.6/site-packages/netaddr/ip/__init__.py", line 314, in __init__
    % (addr, self._module.version))
netaddr.core.AddrFormatError: base address '' is not IPv4

During handling of the above exception, another exception occurred:

Traceback (most recent call last):
  File "/home/petrache/VENV/py3_venv/local/lib/python3.6/site-packages/netaddr/strategy/ipv4.py", line 265, in expand_partial_address
    tokens = ['%d' % int(addr)]
ValueError: invalid literal for int() with base 10: ''

During handling of the above exception, another exception occurred:

Traceback (most recent call last):
  File "/home/petrache/VENV/py3_venv/local/lib/python3.6/site-packages/netaddr/ip/__init__.py", line 928, in __init__
    implicit_prefix, flags)
  File "/home/petrache/VENV/py3_venv/local/lib/python3.6/site-packages/netaddr/ip/__init__.py", line 795, in parse_ip_network
    expanded_addr = _ipv4.expand_partial_address(val1)
  File "/home/petrache/VENV/py3_venv/local/lib/python3.6/site-packages/netaddr/strategy/ipv4.py", line 267, in expand_partial_address
    raise error
netaddr.core.AddrFormatError: invalid partial IPv4 address: ''!

During handling of the above exception, another exception occurred:

Traceback (most recent call last):
  File "/home/petrache/VENV/py3_venv/local/lib/python3.6/site-packages/nornir/core/task.py", line 67, in start
    r = self.task(self, **self.params)
  File "/home/petrache/VENV/py3_venv/local/lib/python3.6/site-packages/nornir/plugins/tasks/networking/napalm_get.py", line 61, in napalm_get
    result[g] = method(**options)
  File "/home/petrache/VENV/py3_venv/src/napalm/napalm/eos/eos.py", line 1159, in get_route_to
    if IPNetwork(destination).version == 6:
  File "/home/petrache/VENV/py3_venv/local/lib/python3.6/site-packages/netaddr/ip/__init__.py", line 938, in __init__
    raise AddrFormatError('invalid IPNetwork %s' % addr)
netaddr.core.AddrFormatError: invalid IPNetwork 

2019-08-21 07:56:45,621 - nornir.core.task -    ERROR -      start() - Host 'arista4': task 'napalm_get' failed with traceback:
Traceback (most recent call last):
  File "/home/petrache/VENV/py3_venv/local/lib/python3.6/site-packages/netaddr/strategy/ipv4.py", line 125, in str_to_int
    return _struct.unpack('>I', _inet_pton(AF_INET, addr))[0]
OSError: illegal IP address string passed to inet_pton

During handling of the above exception, another exception occurred:

Traceback (most recent call last):
  File "/home/petrache/VENV/py3_venv/local/lib/python3.6/site-packages/netaddr/ip/__init__.py", line 311, in __init__
    self._value = self._module.str_to_int(addr, flags)
  File "/home/petrache/VENV/py3_venv/local/lib/python3.6/site-packages/netaddr/strategy/ipv4.py", line 129, in str_to_int
    raise AddrFormatError('%r is not a valid IPv4 address string!' % addr)
netaddr.core.AddrFormatError: '' is not a valid IPv4 address string!

During handling of the above exception, another exception occurred:

Traceback (most recent call last):
  File "/home/petrache/VENV/py3_venv/local/lib/python3.6/site-packages/netaddr/ip/__init__.py", line 791, in parse_ip_network
    ip = IPAddress(val1, module.version, flags=INET_PTON)
  File "/home/petrache/VENV/py3_venv/local/lib/python3.6/site-packages/netaddr/ip/__init__.py", line 314, in __init__
    % (addr, self._module.version))
netaddr.core.AddrFormatError: base address '' is not IPv4

During handling of the above exception, another exception occurred:

Traceback (most recent call last):
  File "/home/petrache/VENV/py3_venv/local/lib/python3.6/site-packages/netaddr/strategy/ipv4.py", line 265, in expand_partial_address
    tokens = ['%d' % int(addr)]
ValueError: invalid literal for int() with base 10: ''

During handling of the above exception, another exception occurred:

Traceback (most recent call last):
  File "/home/petrache/VENV/py3_venv/local/lib/python3.6/site-packages/netaddr/ip/__init__.py", line 928, in __init__
    implicit_prefix, flags)
  File "/home/petrache/VENV/py3_venv/local/lib/python3.6/site-packages/netaddr/ip/__init__.py", line 795, in parse_ip_network
    expanded_addr = _ipv4.expand_partial_address(val1)
  File "/home/petrache/VENV/py3_venv/local/lib/python3.6/site-packages/netaddr/strategy/ipv4.py", line 267, in expand_partial_address
    raise error
netaddr.core.AddrFormatError: invalid partial IPv4 address: ''!

During handling of the above exception, another exception occurred:

Traceback (most recent call last):
  File "/home/petrache/VENV/py3_venv/local/lib/python3.6/site-packages/nornir/core/task.py", line 67, in start
    r = self.task(self, **self.params)
  File "/home/petrache/VENV/py3_venv/local/lib/python3.6/site-packages/nornir/plugins/tasks/networking/napalm_get.py", line 61, in napalm_get
    result[g] = method(**options)
  File "/home/petrache/VENV/py3_venv/src/napalm/napalm/eos/eos.py", line 1159, in get_route_to
    if IPNetwork(destination).version == 6:
  File "/home/petrache/VENV/py3_venv/local/lib/python3.6/site-packages/netaddr/ip/__init__.py", line 938, in __init__
    raise AddrFormatError('invalid IPNetwork %s' % addr)
netaddr.core.AddrFormatError: invalid IPNetwork 

2019-08-21 11:29:15,006 -  nornir.core -     INFO -        run() - Running task 'napalm_get' with args {'getters': ['arp_table']} on 6 hosts
2019-08-21 11:29:20,435 -  nornir.core -     INFO -        run() - Running task 'napalm_get' with args {'getters': ['route_to']} on 6 hosts
2019-08-21 11:29:20,439 - nornir.core.task -    ERROR -      start() - Host 'cisco3': task 'napalm_get' failed with traceback:
Traceback (most recent call last):
  File "/home/petrache/VENV/py3_venv/local/lib/python3.6/site-packages/nornir/core/task.py", line 67, in start
    r = self.task(self, **self.params)
  File "/home/petrache/VENV/py3_venv/local/lib/python3.6/site-packages/nornir/plugins/tasks/networking/napalm_get.py", line 61, in napalm_get
    result[g] = method(**options)
  File "/home/petrache/VENV/py3_venv/src/napalm/napalm/base/base.py", line 1070, in get_route_to
    raise NotImplementedError
NotImplementedError

2019-08-21 11:29:20,440 - nornir.core.task -    ERROR -      start() - Host 'cisco4': task 'napalm_get' failed with traceback:
Traceback (most recent call last):
  File "/home/petrache/VENV/py3_venv/local/lib/python3.6/site-packages/nornir/core/task.py", line 67, in start
    r = self.task(self, **self.params)
  File "/home/petrache/VENV/py3_venv/local/lib/python3.6/site-packages/nornir/plugins/tasks/networking/napalm_get.py", line 61, in napalm_get
    result[g] = method(**options)
  File "/home/petrache/VENV/py3_venv/src/napalm/napalm/base/base.py", line 1070, in get_route_to
    raise NotImplementedError
NotImplementedError

2019-08-21 11:29:20,832 - nornir.core.task -    ERROR -      start() - Host 'arista3': task 'napalm_get' failed with traceback:
Traceback (most recent call last):
  File "/home/petrache/VENV/py3_venv/local/lib/python3.6/site-packages/netaddr/strategy/ipv4.py", line 125, in str_to_int
    return _struct.unpack('>I', _inet_pton(AF_INET, addr))[0]
OSError: illegal IP address string passed to inet_pton

During handling of the above exception, another exception occurred:

Traceback (most recent call last):
  File "/home/petrache/VENV/py3_venv/local/lib/python3.6/site-packages/netaddr/ip/__init__.py", line 311, in __init__
    self._value = self._module.str_to_int(addr, flags)
  File "/home/petrache/VENV/py3_venv/local/lib/python3.6/site-packages/netaddr/strategy/ipv4.py", line 129, in str_to_int
    raise AddrFormatError('%r is not a valid IPv4 address string!' % addr)
netaddr.core.AddrFormatError: '' is not a valid IPv4 address string!

During handling of the above exception, another exception occurred:

Traceback (most recent call last):
  File "/home/petrache/VENV/py3_venv/local/lib/python3.6/site-packages/netaddr/ip/__init__.py", line 791, in parse_ip_network
    ip = IPAddress(val1, module.version, flags=INET_PTON)
  File "/home/petrache/VENV/py3_venv/local/lib/python3.6/site-packages/netaddr/ip/__init__.py", line 314, in __init__
    % (addr, self._module.version))
netaddr.core.AddrFormatError: base address '' is not IPv4

During handling of the above exception, another exception occurred:

Traceback (most recent call last):
  File "/home/petrache/VENV/py3_venv/local/lib/python3.6/site-packages/netaddr/strategy/ipv4.py", line 265, in expand_partial_address
    tokens = ['%d' % int(addr)]
ValueError: invalid literal for int() with base 10: ''

During handling of the above exception, another exception occurred:

Traceback (most recent call last):
  File "/home/petrache/VENV/py3_venv/local/lib/python3.6/site-packages/netaddr/ip/__init__.py", line 928, in __init__
    implicit_prefix, flags)
  File "/home/petrache/VENV/py3_venv/local/lib/python3.6/site-packages/netaddr/ip/__init__.py", line 795, in parse_ip_network
    expanded_addr = _ipv4.expand_partial_address(val1)
  File "/home/petrache/VENV/py3_venv/local/lib/python3.6/site-packages/netaddr/strategy/ipv4.py", line 267, in expand_partial_address
    raise error
netaddr.core.AddrFormatError: invalid partial IPv4 address: ''!

During handling of the above exception, another exception occurred:

Traceback (most recent call last):
  File "/home/petrache/VENV/py3_venv/local/lib/python3.6/site-packages/nornir/core/task.py", line 67, in start
    r = self.task(self, **self.params)
  File "/home/petrache/VENV/py3_venv/local/lib/python3.6/site-packages/nornir/plugins/tasks/networking/napalm_get.py", line 61, in napalm_get
    result[g] = method(**options)
  File "/home/petrache/VENV/py3_venv/src/napalm/napalm/eos/eos.py", line 1159, in get_route_to
    if IPNetwork(destination).version == 6:
  File "/home/petrache/VENV/py3_venv/local/lib/python3.6/site-packages/netaddr/ip/__init__.py", line 938, in __init__
    raise AddrFormatError('invalid IPNetwork %s' % addr)
netaddr.core.AddrFormatError: invalid IPNetwork 

2019-08-21 11:29:20,837 - nornir.core.task -    ERROR -      start() - Host 'arista1': task 'napalm_get' failed with traceback:
Traceback (most recent call last):
  File "/home/petrache/VENV/py3_venv/local/lib/python3.6/site-packages/netaddr/strategy/ipv4.py", line 125, in str_to_int
    return _struct.unpack('>I', _inet_pton(AF_INET, addr))[0]
OSError: illegal IP address string passed to inet_pton

During handling of the above exception, another exception occurred:

Traceback (most recent call last):
  File "/home/petrache/VENV/py3_venv/local/lib/python3.6/site-packages/netaddr/ip/__init__.py", line 311, in __init__
    self._value = self._module.str_to_int(addr, flags)
  File "/home/petrache/VENV/py3_venv/local/lib/python3.6/site-packages/netaddr/strategy/ipv4.py", line 129, in str_to_int
    raise AddrFormatError('%r is not a valid IPv4 address string!' % addr)
netaddr.core.AddrFormatError: '' is not a valid IPv4 address string!

During handling of the above exception, another exception occurred:

Traceback (most recent call last):
  File "/home/petrache/VENV/py3_venv/local/lib/python3.6/site-packages/netaddr/ip/__init__.py", line 791, in parse_ip_network
    ip = IPAddress(val1, module.version, flags=INET_PTON)
  File "/home/petrache/VENV/py3_venv/local/lib/python3.6/site-packages/netaddr/ip/__init__.py", line 314, in __init__
    % (addr, self._module.version))
netaddr.core.AddrFormatError: base address '' is not IPv4

During handling of the above exception, another exception occurred:

Traceback (most recent call last):
  File "/home/petrache/VENV/py3_venv/local/lib/python3.6/site-packages/netaddr/strategy/ipv4.py", line 265, in expand_partial_address
    tokens = ['%d' % int(addr)]
ValueError: invalid literal for int() with base 10: ''

During handling of the above exception, another exception occurred:

Traceback (most recent call last):
  File "/home/petrache/VENV/py3_venv/local/lib/python3.6/site-packages/netaddr/ip/__init__.py", line 928, in __init__
    implicit_prefix, flags)
  File "/home/petrache/VENV/py3_venv/local/lib/python3.6/site-packages/netaddr/ip/__init__.py", line 795, in parse_ip_network
    expanded_addr = _ipv4.expand_partial_address(val1)
  File "/home/petrache/VENV/py3_venv/local/lib/python3.6/site-packages/netaddr/strategy/ipv4.py", line 267, in expand_partial_address
    raise error
netaddr.core.AddrFormatError: invalid partial IPv4 address: ''!

During handling of the above exception, another exception occurred:

Traceback (most recent call last):
  File "/home/petrache/VENV/py3_venv/local/lib/python3.6/site-packages/nornir/core/task.py", line 67, in start
    r = self.task(self, **self.params)
  File "/home/petrache/VENV/py3_venv/local/lib/python3.6/site-packages/nornir/plugins/tasks/networking/napalm_get.py", line 61, in napalm_get
    result[g] = method(**options)
  File "/home/petrache/VENV/py3_venv/src/napalm/napalm/eos/eos.py", line 1159, in get_route_to
    if IPNetwork(destination).version == 6:
  File "/home/petrache/VENV/py3_venv/local/lib/python3.6/site-packages/netaddr/ip/__init__.py", line 938, in __init__
    raise AddrFormatError('invalid IPNetwork %s' % addr)
netaddr.core.AddrFormatError: invalid IPNetwork 

2019-08-21 11:29:20,854 - nornir.core.task -    ERROR -      start() - Host 'arista4': task 'napalm_get' failed with traceback:
Traceback (most recent call last):
  File "/home/petrache/VENV/py3_venv/local/lib/python3.6/site-packages/netaddr/strategy/ipv4.py", line 125, in str_to_int
    return _struct.unpack('>I', _inet_pton(AF_INET, addr))[0]
OSError: illegal IP address string passed to inet_pton

During handling of the above exception, another exception occurred:

Traceback (most recent call last):
  File "/home/petrache/VENV/py3_venv/local/lib/python3.6/site-packages/netaddr/ip/__init__.py", line 311, in __init__
    self._value = self._module.str_to_int(addr, flags)
  File "/home/petrache/VENV/py3_venv/local/lib/python3.6/site-packages/netaddr/strategy/ipv4.py", line 129, in str_to_int
    raise AddrFormatError('%r is not a valid IPv4 address string!' % addr)
netaddr.core.AddrFormatError: '' is not a valid IPv4 address string!

During handling of the above exception, another exception occurred:

Traceback (most recent call last):
  File "/home/petrache/VENV/py3_venv/local/lib/python3.6/site-packages/netaddr/ip/__init__.py", line 791, in parse_ip_network
    ip = IPAddress(val1, module.version, flags=INET_PTON)
  File "/home/petrache/VENV/py3_venv/local/lib/python3.6/site-packages/netaddr/ip/__init__.py", line 314, in __init__
    % (addr, self._module.version))
netaddr.core.AddrFormatError: base address '' is not IPv4

During handling of the above exception, another exception occurred:

Traceback (most recent call last):
  File "/home/petrache/VENV/py3_venv/local/lib/python3.6/site-packages/netaddr/strategy/ipv4.py", line 265, in expand_partial_address
    tokens = ['%d' % int(addr)]
ValueError: invalid literal for int() with base 10: ''

During handling of the above exception, another exception occurred:

Traceback (most recent call last):
  File "/home/petrache/VENV/py3_venv/local/lib/python3.6/site-packages/netaddr/ip/__init__.py", line 928, in __init__
    implicit_prefix, flags)
  File "/home/petrache/VENV/py3_venv/local/lib/python3.6/site-packages/netaddr/ip/__init__.py", line 795, in parse_ip_network
    expanded_addr = _ipv4.expand_partial_address(val1)
  File "/home/petrache/VENV/py3_venv/local/lib/python3.6/site-packages/netaddr/strategy/ipv4.py", line 267, in expand_partial_address
    raise error
netaddr.core.AddrFormatError: invalid partial IPv4 address: ''!

During handling of the above exception, another exception occurred:

Traceback (most recent call last):
  File "/home/petrache/VENV/py3_venv/local/lib/python3.6/site-packages/nornir/core/task.py", line 67, in start
    r = self.task(self, **self.params)
  File "/home/petrache/VENV/py3_venv/local/lib/python3.6/site-packages/nornir/plugins/tasks/networking/napalm_get.py", line 61, in napalm_get
    result[g] = method(**options)
  File "/home/petrache/VENV/py3_venv/src/napalm/napalm/eos/eos.py", line 1159, in get_route_to
    if IPNetwork(destination).version == 6:
  File "/home/petrache/VENV/py3_venv/local/lib/python3.6/site-packages/netaddr/ip/__init__.py", line 938, in __init__
    raise AddrFormatError('invalid IPNetwork %s' % addr)
netaddr.core.AddrFormatError: invalid IPNetwork 

2019-08-21 11:29:20,866 - nornir.core.task -    ERROR -      start() - Host 'arista2': task 'napalm_get' failed with traceback:
Traceback (most recent call last):
  File "/home/petrache/VENV/py3_venv/local/lib/python3.6/site-packages/netaddr/strategy/ipv4.py", line 125, in str_to_int
    return _struct.unpack('>I', _inet_pton(AF_INET, addr))[0]
OSError: illegal IP address string passed to inet_pton

During handling of the above exception, another exception occurred:

Traceback (most recent call last):
  File "/home/petrache/VENV/py3_venv/local/lib/python3.6/site-packages/netaddr/ip/__init__.py", line 311, in __init__
    self._value = self._module.str_to_int(addr, flags)
  File "/home/petrache/VENV/py3_venv/local/lib/python3.6/site-packages/netaddr/strategy/ipv4.py", line 129, in str_to_int
    raise AddrFormatError('%r is not a valid IPv4 address string!' % addr)
netaddr.core.AddrFormatError: '' is not a valid IPv4 address string!

During handling of the above exception, another exception occurred:

Traceback (most recent call last):
  File "/home/petrache/VENV/py3_venv/local/lib/python3.6/site-packages/netaddr/ip/__init__.py", line 791, in parse_ip_network
    ip = IPAddress(val1, module.version, flags=INET_PTON)
  File "/home/petrache/VENV/py3_venv/local/lib/python3.6/site-packages/netaddr/ip/__init__.py", line 314, in __init__
    % (addr, self._module.version))
netaddr.core.AddrFormatError: base address '' is not IPv4

During handling of the above exception, another exception occurred:

Traceback (most recent call last):
  File "/home/petrache/VENV/py3_venv/local/lib/python3.6/site-packages/netaddr/strategy/ipv4.py", line 265, in expand_partial_address
    tokens = ['%d' % int(addr)]
ValueError: invalid literal for int() with base 10: ''

During handling of the above exception, another exception occurred:

Traceback (most recent call last):
  File "/home/petrache/VENV/py3_venv/local/lib/python3.6/site-packages/netaddr/ip/__init__.py", line 928, in __init__
    implicit_prefix, flags)
  File "/home/petrache/VENV/py3_venv/local/lib/python3.6/site-packages/netaddr/ip/__init__.py", line 795, in parse_ip_network
    expanded_addr = _ipv4.expand_partial_address(val1)
  File "/home/petrache/VENV/py3_venv/local/lib/python3.6/site-packages/netaddr/strategy/ipv4.py", line 267, in expand_partial_address
    raise error
netaddr.core.AddrFormatError: invalid partial IPv4 address: ''!

During handling of the above exception, another exception occurred:

Traceback (most recent call last):
  File "/home/petrache/VENV/py3_venv/local/lib/python3.6/site-packages/nornir/core/task.py", line 67, in start
    r = self.task(self, **self.params)
  File "/home/petrache/VENV/py3_venv/local/lib/python3.6/site-packages/nornir/plugins/tasks/networking/napalm_get.py", line 61, in napalm_get
    result[g] = method(**options)
  File "/home/petrache/VENV/py3_venv/src/napalm/napalm/eos/eos.py", line 1159, in get_route_to
    if IPNetwork(destination).version == 6:
  File "/home/petrache/VENV/py3_venv/local/lib/python3.6/site-packages/netaddr/ip/__init__.py", line 938, in __init__
    raise AddrFormatError('invalid IPNetwork %s' % addr)
netaddr.core.AddrFormatError: invalid IPNetwork 

2019-08-21 11:29:47,920 -  nornir.core -     INFO -        run() - Running task 'napalm_get' with args {'getters': ['arp_table']} on 6 hosts
2019-08-21 11:29:53,392 -  nornir.core -     INFO -        run() - Running task 'napalm_get' with args {'getters': ['get_route_to']} on 6 hosts
2019-08-21 11:29:53,395 - nornir.core.task -    ERROR -      start() - Host 'cisco3': task 'napalm_get' failed with traceback:
Traceback (most recent call last):
  File "/home/petrache/VENV/py3_venv/local/lib/python3.6/site-packages/nornir/core/task.py", line 67, in start
    r = self.task(self, **self.params)
  File "/home/petrache/VENV/py3_venv/local/lib/python3.6/site-packages/nornir/plugins/tasks/networking/napalm_get.py", line 61, in napalm_get
    result[g] = method(**options)
  File "/home/petrache/VENV/py3_venv/src/napalm/napalm/base/base.py", line 1070, in get_route_to
    raise NotImplementedError
NotImplementedError

2019-08-21 11:29:53,396 - nornir.core.task -    ERROR -      start() - Host 'cisco4': task 'napalm_get' failed with traceback:
Traceback (most recent call last):
  File "/home/petrache/VENV/py3_venv/local/lib/python3.6/site-packages/nornir/core/task.py", line 67, in start
    r = self.task(self, **self.params)
  File "/home/petrache/VENV/py3_venv/local/lib/python3.6/site-packages/nornir/plugins/tasks/networking/napalm_get.py", line 61, in napalm_get
    result[g] = method(**options)
  File "/home/petrache/VENV/py3_venv/src/napalm/napalm/base/base.py", line 1070, in get_route_to
    raise NotImplementedError
NotImplementedError

2019-08-21 11:29:53,779 - nornir.core.task -    ERROR -      start() - Host 'arista2': task 'napalm_get' failed with traceback:
Traceback (most recent call last):
  File "/home/petrache/VENV/py3_venv/local/lib/python3.6/site-packages/netaddr/strategy/ipv4.py", line 125, in str_to_int
    return _struct.unpack('>I', _inet_pton(AF_INET, addr))[0]
OSError: illegal IP address string passed to inet_pton

During handling of the above exception, another exception occurred:

Traceback (most recent call last):
  File "/home/petrache/VENV/py3_venv/local/lib/python3.6/site-packages/netaddr/ip/__init__.py", line 311, in __init__
    self._value = self._module.str_to_int(addr, flags)
  File "/home/petrache/VENV/py3_venv/local/lib/python3.6/site-packages/netaddr/strategy/ipv4.py", line 129, in str_to_int
    raise AddrFormatError('%r is not a valid IPv4 address string!' % addr)
netaddr.core.AddrFormatError: '' is not a valid IPv4 address string!

During handling of the above exception, another exception occurred:

Traceback (most recent call last):
  File "/home/petrache/VENV/py3_venv/local/lib/python3.6/site-packages/netaddr/ip/__init__.py", line 791, in parse_ip_network
    ip = IPAddress(val1, module.version, flags=INET_PTON)
  File "/home/petrache/VENV/py3_venv/local/lib/python3.6/site-packages/netaddr/ip/__init__.py", line 314, in __init__
    % (addr, self._module.version))
netaddr.core.AddrFormatError: base address '' is not IPv4

During handling of the above exception, another exception occurred:

Traceback (most recent call last):
  File "/home/petrache/VENV/py3_venv/local/lib/python3.6/site-packages/netaddr/strategy/ipv4.py", line 265, in expand_partial_address
    tokens = ['%d' % int(addr)]
ValueError: invalid literal for int() with base 10: ''

During handling of the above exception, another exception occurred:

Traceback (most recent call last):
  File "/home/petrache/VENV/py3_venv/local/lib/python3.6/site-packages/netaddr/ip/__init__.py", line 928, in __init__
    implicit_prefix, flags)
  File "/home/petrache/VENV/py3_venv/local/lib/python3.6/site-packages/netaddr/ip/__init__.py", line 795, in parse_ip_network
    expanded_addr = _ipv4.expand_partial_address(val1)
  File "/home/petrache/VENV/py3_venv/local/lib/python3.6/site-packages/netaddr/strategy/ipv4.py", line 267, in expand_partial_address
    raise error
netaddr.core.AddrFormatError: invalid partial IPv4 address: ''!

During handling of the above exception, another exception occurred:

Traceback (most recent call last):
  File "/home/petrache/VENV/py3_venv/local/lib/python3.6/site-packages/nornir/core/task.py", line 67, in start
    r = self.task(self, **self.params)
  File "/home/petrache/VENV/py3_venv/local/lib/python3.6/site-packages/nornir/plugins/tasks/networking/napalm_get.py", line 61, in napalm_get
    result[g] = method(**options)
  File "/home/petrache/VENV/py3_venv/src/napalm/napalm/eos/eos.py", line 1159, in get_route_to
    if IPNetwork(destination).version == 6:
  File "/home/petrache/VENV/py3_venv/local/lib/python3.6/site-packages/netaddr/ip/__init__.py", line 938, in __init__
    raise AddrFormatError('invalid IPNetwork %s' % addr)
netaddr.core.AddrFormatError: invalid IPNetwork 

2019-08-21 11:29:53,788 - nornir.core.task -    ERROR -      start() - Host 'arista1': task 'napalm_get' failed with traceback:
Traceback (most recent call last):
  File "/home/petrache/VENV/py3_venv/local/lib/python3.6/site-packages/netaddr/strategy/ipv4.py", line 125, in str_to_int
    return _struct.unpack('>I', _inet_pton(AF_INET, addr))[0]
OSError: illegal IP address string passed to inet_pton

During handling of the above exception, another exception occurred:

Traceback (most recent call last):
  File "/home/petrache/VENV/py3_venv/local/lib/python3.6/site-packages/netaddr/ip/__init__.py", line 311, in __init__
    self._value = self._module.str_to_int(addr, flags)
  File "/home/petrache/VENV/py3_venv/local/lib/python3.6/site-packages/netaddr/strategy/ipv4.py", line 129, in str_to_int
    raise AddrFormatError('%r is not a valid IPv4 address string!' % addr)
netaddr.core.AddrFormatError: '' is not a valid IPv4 address string!

During handling of the above exception, another exception occurred:

Traceback (most recent call last):
  File "/home/petrache/VENV/py3_venv/local/lib/python3.6/site-packages/netaddr/ip/__init__.py", line 791, in parse_ip_network
    ip = IPAddress(val1, module.version, flags=INET_PTON)
  File "/home/petrache/VENV/py3_venv/local/lib/python3.6/site-packages/netaddr/ip/__init__.py", line 314, in __init__
    % (addr, self._module.version))
netaddr.core.AddrFormatError: base address '' is not IPv4

During handling of the above exception, another exception occurred:

Traceback (most recent call last):
  File "/home/petrache/VENV/py3_venv/local/lib/python3.6/site-packages/netaddr/strategy/ipv4.py", line 265, in expand_partial_address
    tokens = ['%d' % int(addr)]
ValueError: invalid literal for int() with base 10: ''

During handling of the above exception, another exception occurred:

Traceback (most recent call last):
  File "/home/petrache/VENV/py3_venv/local/lib/python3.6/site-packages/netaddr/ip/__init__.py", line 928, in __init__
    implicit_prefix, flags)
  File "/home/petrache/VENV/py3_venv/local/lib/python3.6/site-packages/netaddr/ip/__init__.py", line 795, in parse_ip_network
    expanded_addr = _ipv4.expand_partial_address(val1)
  File "/home/petrache/VENV/py3_venv/local/lib/python3.6/site-packages/netaddr/strategy/ipv4.py", line 267, in expand_partial_address
    raise error
netaddr.core.AddrFormatError: invalid partial IPv4 address: ''!

During handling of the above exception, another exception occurred:

Traceback (most recent call last):
  File "/home/petrache/VENV/py3_venv/local/lib/python3.6/site-packages/nornir/core/task.py", line 67, in start
    r = self.task(self, **self.params)
  File "/home/petrache/VENV/py3_venv/local/lib/python3.6/site-packages/nornir/plugins/tasks/networking/napalm_get.py", line 61, in napalm_get
    result[g] = method(**options)
  File "/home/petrache/VENV/py3_venv/src/napalm/napalm/eos/eos.py", line 1159, in get_route_to
    if IPNetwork(destination).version == 6:
  File "/home/petrache/VENV/py3_venv/local/lib/python3.6/site-packages/netaddr/ip/__init__.py", line 938, in __init__
    raise AddrFormatError('invalid IPNetwork %s' % addr)
netaddr.core.AddrFormatError: invalid IPNetwork 

2019-08-21 11:29:53,831 - nornir.core.task -    ERROR -      start() - Host 'arista4': task 'napalm_get' failed with traceback:
Traceback (most recent call last):
  File "/home/petrache/VENV/py3_venv/local/lib/python3.6/site-packages/netaddr/strategy/ipv4.py", line 125, in str_to_int
    return _struct.unpack('>I', _inet_pton(AF_INET, addr))[0]
OSError: illegal IP address string passed to inet_pton

During handling of the above exception, another exception occurred:

Traceback (most recent call last):
  File "/home/petrache/VENV/py3_venv/local/lib/python3.6/site-packages/netaddr/ip/__init__.py", line 311, in __init__
    self._value = self._module.str_to_int(addr, flags)
  File "/home/petrache/VENV/py3_venv/local/lib/python3.6/site-packages/netaddr/strategy/ipv4.py", line 129, in str_to_int
    raise AddrFormatError('%r is not a valid IPv4 address string!' % addr)
netaddr.core.AddrFormatError: '' is not a valid IPv4 address string!

During handling of the above exception, another exception occurred:

Traceback (most recent call last):
  File "/home/petrache/VENV/py3_venv/local/lib/python3.6/site-packages/netaddr/ip/__init__.py", line 791, in parse_ip_network
    ip = IPAddress(val1, module.version, flags=INET_PTON)
  File "/home/petrache/VENV/py3_venv/local/lib/python3.6/site-packages/netaddr/ip/__init__.py", line 314, in __init__
    % (addr, self._module.version))
netaddr.core.AddrFormatError: base address '' is not IPv4

During handling of the above exception, another exception occurred:

Traceback (most recent call last):
  File "/home/petrache/VENV/py3_venv/local/lib/python3.6/site-packages/netaddr/strategy/ipv4.py", line 265, in expand_partial_address
    tokens = ['%d' % int(addr)]
ValueError: invalid literal for int() with base 10: ''

During handling of the above exception, another exception occurred:

Traceback (most recent call last):
  File "/home/petrache/VENV/py3_venv/local/lib/python3.6/site-packages/netaddr/ip/__init__.py", line 928, in __init__
    implicit_prefix, flags)
  File "/home/petrache/VENV/py3_venv/local/lib/python3.6/site-packages/netaddr/ip/__init__.py", line 795, in parse_ip_network
    expanded_addr = _ipv4.expand_partial_address(val1)
  File "/home/petrache/VENV/py3_venv/local/lib/python3.6/site-packages/netaddr/strategy/ipv4.py", line 267, in expand_partial_address
    raise error
netaddr.core.AddrFormatError: invalid partial IPv4 address: ''!

During handling of the above exception, another exception occurred:

Traceback (most recent call last):
  File "/home/petrache/VENV/py3_venv/local/lib/python3.6/site-packages/nornir/core/task.py", line 67, in start
    r = self.task(self, **self.params)
  File "/home/petrache/VENV/py3_venv/local/lib/python3.6/site-packages/nornir/plugins/tasks/networking/napalm_get.py", line 61, in napalm_get
    result[g] = method(**options)
  File "/home/petrache/VENV/py3_venv/src/napalm/napalm/eos/eos.py", line 1159, in get_route_to
    if IPNetwork(destination).version == 6:
  File "/home/petrache/VENV/py3_venv/local/lib/python3.6/site-packages/netaddr/ip/__init__.py", line 938, in __init__
    raise AddrFormatError('invalid IPNetwork %s' % addr)
netaddr.core.AddrFormatError: invalid IPNetwork 

2019-08-21 11:29:53,871 - nornir.core.task -    ERROR -      start() - Host 'arista3': task 'napalm_get' failed with traceback:
Traceback (most recent call last):
  File "/home/petrache/VENV/py3_venv/local/lib/python3.6/site-packages/netaddr/strategy/ipv4.py", line 125, in str_to_int
    return _struct.unpack('>I', _inet_pton(AF_INET, addr))[0]
OSError: illegal IP address string passed to inet_pton

During handling of the above exception, another exception occurred:

Traceback (most recent call last):
  File "/home/petrache/VENV/py3_venv/local/lib/python3.6/site-packages/netaddr/ip/__init__.py", line 311, in __init__
    self._value = self._module.str_to_int(addr, flags)
  File "/home/petrache/VENV/py3_venv/local/lib/python3.6/site-packages/netaddr/strategy/ipv4.py", line 129, in str_to_int
    raise AddrFormatError('%r is not a valid IPv4 address string!' % addr)
netaddr.core.AddrFormatError: '' is not a valid IPv4 address string!

During handling of the above exception, another exception occurred:

Traceback (most recent call last):
  File "/home/petrache/VENV/py3_venv/local/lib/python3.6/site-packages/netaddr/ip/__init__.py", line 791, in parse_ip_network
    ip = IPAddress(val1, module.version, flags=INET_PTON)
  File "/home/petrache/VENV/py3_venv/local/lib/python3.6/site-packages/netaddr/ip/__init__.py", line 314, in __init__
    % (addr, self._module.version))
netaddr.core.AddrFormatError: base address '' is not IPv4

During handling of the above exception, another exception occurred:

Traceback (most recent call last):
  File "/home/petrache/VENV/py3_venv/local/lib/python3.6/site-packages/netaddr/strategy/ipv4.py", line 265, in expand_partial_address
    tokens = ['%d' % int(addr)]
ValueError: invalid literal for int() with base 10: ''

During handling of the above exception, another exception occurred:

Traceback (most recent call last):
  File "/home/petrache/VENV/py3_venv/local/lib/python3.6/site-packages/netaddr/ip/__init__.py", line 928, in __init__
    implicit_prefix, flags)
  File "/home/petrache/VENV/py3_venv/local/lib/python3.6/site-packages/netaddr/ip/__init__.py", line 795, in parse_ip_network
    expanded_addr = _ipv4.expand_partial_address(val1)
  File "/home/petrache/VENV/py3_venv/local/lib/python3.6/site-packages/netaddr/strategy/ipv4.py", line 267, in expand_partial_address
    raise error
netaddr.core.AddrFormatError: invalid partial IPv4 address: ''!

During handling of the above exception, another exception occurred:

Traceback (most recent call last):
  File "/home/petrache/VENV/py3_venv/local/lib/python3.6/site-packages/nornir/core/task.py", line 67, in start
    r = self.task(self, **self.params)
  File "/home/petrache/VENV/py3_venv/local/lib/python3.6/site-packages/nornir/plugins/tasks/networking/napalm_get.py", line 61, in napalm_get
    result[g] = method(**options)
  File "/home/petrache/VENV/py3_venv/src/napalm/napalm/eos/eos.py", line 1159, in get_route_to
    if IPNetwork(destination).version == 6:
  File "/home/petrache/VENV/py3_venv/local/lib/python3.6/site-packages/netaddr/ip/__init__.py", line 938, in __init__
    raise AddrFormatError('invalid IPNetwork %s' % addr)
netaddr.core.AddrFormatError: invalid IPNetwork 

2019-08-21 11:31:23,087 -  nornir.core -     INFO -        run() - Running task 'napalm_get' with args {'getters': ['arp_table']} on 6 hosts
2019-08-21 11:31:28,648 -  nornir.core -     INFO -        run() - Running task 'napalm_get' with args {'getters': ['get_route_to']} on 6 hosts
2019-08-21 11:31:28,652 - nornir.core.task -    ERROR -      start() - Host 'cisco3': task 'napalm_get' failed with traceback:
Traceback (most recent call last):
  File "/home/petrache/VENV/py3_venv/local/lib/python3.6/site-packages/nornir/core/task.py", line 67, in start
    r = self.task(self, **self.params)
  File "/home/petrache/VENV/py3_venv/local/lib/python3.6/site-packages/nornir/plugins/tasks/networking/napalm_get.py", line 61, in napalm_get
    result[g] = method(**options)
  File "/home/petrache/VENV/py3_venv/src/napalm/napalm/base/base.py", line 1070, in get_route_to
    raise NotImplementedError
NotImplementedError

2019-08-21 11:31:28,652 - nornir.core.task -    ERROR -      start() - Host 'cisco4': task 'napalm_get' failed with traceback:
Traceback (most recent call last):
  File "/home/petrache/VENV/py3_venv/local/lib/python3.6/site-packages/nornir/core/task.py", line 67, in start
    r = self.task(self, **self.params)
  File "/home/petrache/VENV/py3_venv/local/lib/python3.6/site-packages/nornir/plugins/tasks/networking/napalm_get.py", line 61, in napalm_get
    result[g] = method(**options)
  File "/home/petrache/VENV/py3_venv/src/napalm/napalm/base/base.py", line 1070, in get_route_to
    raise NotImplementedError
NotImplementedError

2019-08-21 11:31:29,034 - nornir.core.task -    ERROR -      start() - Host 'arista4': task 'napalm_get' failed with traceback:
Traceback (most recent call last):
  File "/home/petrache/VENV/py3_venv/local/lib/python3.6/site-packages/netaddr/strategy/ipv4.py", line 125, in str_to_int
    return _struct.unpack('>I', _inet_pton(AF_INET, addr))[0]
OSError: illegal IP address string passed to inet_pton

During handling of the above exception, another exception occurred:

Traceback (most recent call last):
  File "/home/petrache/VENV/py3_venv/local/lib/python3.6/site-packages/netaddr/ip/__init__.py", line 311, in __init__
    self._value = self._module.str_to_int(addr, flags)
  File "/home/petrache/VENV/py3_venv/local/lib/python3.6/site-packages/netaddr/strategy/ipv4.py", line 129, in str_to_int
    raise AddrFormatError('%r is not a valid IPv4 address string!' % addr)
netaddr.core.AddrFormatError: '' is not a valid IPv4 address string!

During handling of the above exception, another exception occurred:

Traceback (most recent call last):
  File "/home/petrache/VENV/py3_venv/local/lib/python3.6/site-packages/netaddr/ip/__init__.py", line 791, in parse_ip_network
    ip = IPAddress(val1, module.version, flags=INET_PTON)
  File "/home/petrache/VENV/py3_venv/local/lib/python3.6/site-packages/netaddr/ip/__init__.py", line 314, in __init__
    % (addr, self._module.version))
netaddr.core.AddrFormatError: base address '' is not IPv4

During handling of the above exception, another exception occurred:

Traceback (most recent call last):
  File "/home/petrache/VENV/py3_venv/local/lib/python3.6/site-packages/netaddr/strategy/ipv4.py", line 265, in expand_partial_address
    tokens = ['%d' % int(addr)]
ValueError: invalid literal for int() with base 10: ''

During handling of the above exception, another exception occurred:

Traceback (most recent call last):
  File "/home/petrache/VENV/py3_venv/local/lib/python3.6/site-packages/netaddr/ip/__init__.py", line 928, in __init__
    implicit_prefix, flags)
  File "/home/petrache/VENV/py3_venv/local/lib/python3.6/site-packages/netaddr/ip/__init__.py", line 795, in parse_ip_network
    expanded_addr = _ipv4.expand_partial_address(val1)
  File "/home/petrache/VENV/py3_venv/local/lib/python3.6/site-packages/netaddr/strategy/ipv4.py", line 267, in expand_partial_address
    raise error
netaddr.core.AddrFormatError: invalid partial IPv4 address: ''!

During handling of the above exception, another exception occurred:

Traceback (most recent call last):
  File "/home/petrache/VENV/py3_venv/local/lib/python3.6/site-packages/nornir/core/task.py", line 67, in start
    r = self.task(self, **self.params)
  File "/home/petrache/VENV/py3_venv/local/lib/python3.6/site-packages/nornir/plugins/tasks/networking/napalm_get.py", line 61, in napalm_get
    result[g] = method(**options)
  File "/home/petrache/VENV/py3_venv/src/napalm/napalm/eos/eos.py", line 1159, in get_route_to
    if IPNetwork(destination).version == 6:
  File "/home/petrache/VENV/py3_venv/local/lib/python3.6/site-packages/netaddr/ip/__init__.py", line 938, in __init__
    raise AddrFormatError('invalid IPNetwork %s' % addr)
netaddr.core.AddrFormatError: invalid IPNetwork 

2019-08-21 11:31:29,056 - nornir.core.task -    ERROR -      start() - Host 'arista3': task 'napalm_get' failed with traceback:
Traceback (most recent call last):
  File "/home/petrache/VENV/py3_venv/local/lib/python3.6/site-packages/netaddr/strategy/ipv4.py", line 125, in str_to_int
    return _struct.unpack('>I', _inet_pton(AF_INET, addr))[0]
OSError: illegal IP address string passed to inet_pton

During handling of the above exception, another exception occurred:

Traceback (most recent call last):
  File "/home/petrache/VENV/py3_venv/local/lib/python3.6/site-packages/netaddr/ip/__init__.py", line 311, in __init__
    self._value = self._module.str_to_int(addr, flags)
  File "/home/petrache/VENV/py3_venv/local/lib/python3.6/site-packages/netaddr/strategy/ipv4.py", line 129, in str_to_int
    raise AddrFormatError('%r is not a valid IPv4 address string!' % addr)
netaddr.core.AddrFormatError: '' is not a valid IPv4 address string!

During handling of the above exception, another exception occurred:

Traceback (most recent call last):
  File "/home/petrache/VENV/py3_venv/local/lib/python3.6/site-packages/netaddr/ip/__init__.py", line 791, in parse_ip_network
    ip = IPAddress(val1, module.version, flags=INET_PTON)
  File "/home/petrache/VENV/py3_venv/local/lib/python3.6/site-packages/netaddr/ip/__init__.py", line 314, in __init__
    % (addr, self._module.version))
netaddr.core.AddrFormatError: base address '' is not IPv4

During handling of the above exception, another exception occurred:

Traceback (most recent call last):
  File "/home/petrache/VENV/py3_venv/local/lib/python3.6/site-packages/netaddr/strategy/ipv4.py", line 265, in expand_partial_address
    tokens = ['%d' % int(addr)]
ValueError: invalid literal for int() with base 10: ''

During handling of the above exception, another exception occurred:

Traceback (most recent call last):
  File "/home/petrache/VENV/py3_venv/local/lib/python3.6/site-packages/netaddr/ip/__init__.py", line 928, in __init__
    implicit_prefix, flags)
  File "/home/petrache/VENV/py3_venv/local/lib/python3.6/site-packages/netaddr/ip/__init__.py", line 795, in parse_ip_network
    expanded_addr = _ipv4.expand_partial_address(val1)
  File "/home/petrache/VENV/py3_venv/local/lib/python3.6/site-packages/netaddr/strategy/ipv4.py", line 267, in expand_partial_address
    raise error
netaddr.core.AddrFormatError: invalid partial IPv4 address: ''!

During handling of the above exception, another exception occurred:

Traceback (most recent call last):
  File "/home/petrache/VENV/py3_venv/local/lib/python3.6/site-packages/nornir/core/task.py", line 67, in start
    r = self.task(self, **self.params)
  File "/home/petrache/VENV/py3_venv/local/lib/python3.6/site-packages/nornir/plugins/tasks/networking/napalm_get.py", line 61, in napalm_get
    result[g] = method(**options)
  File "/home/petrache/VENV/py3_venv/src/napalm/napalm/eos/eos.py", line 1159, in get_route_to
    if IPNetwork(destination).version == 6:
  File "/home/petrache/VENV/py3_venv/local/lib/python3.6/site-packages/netaddr/ip/__init__.py", line 938, in __init__
    raise AddrFormatError('invalid IPNetwork %s' % addr)
netaddr.core.AddrFormatError: invalid IPNetwork 

2019-08-21 11:31:29,058 - nornir.core.task -    ERROR -      start() - Host 'arista2': task 'napalm_get' failed with traceback:
Traceback (most recent call last):
  File "/home/petrache/VENV/py3_venv/local/lib/python3.6/site-packages/netaddr/strategy/ipv4.py", line 125, in str_to_int
    return _struct.unpack('>I', _inet_pton(AF_INET, addr))[0]
OSError: illegal IP address string passed to inet_pton

During handling of the above exception, another exception occurred:

Traceback (most recent call last):
  File "/home/petrache/VENV/py3_venv/local/lib/python3.6/site-packages/netaddr/ip/__init__.py", line 311, in __init__
    self._value = self._module.str_to_int(addr, flags)
  File "/home/petrache/VENV/py3_venv/local/lib/python3.6/site-packages/netaddr/strategy/ipv4.py", line 129, in str_to_int
    raise AddrFormatError('%r is not a valid IPv4 address string!' % addr)
netaddr.core.AddrFormatError: '' is not a valid IPv4 address string!

During handling of the above exception, another exception occurred:

Traceback (most recent call last):
  File "/home/petrache/VENV/py3_venv/local/lib/python3.6/site-packages/netaddr/ip/__init__.py", line 791, in parse_ip_network
    ip = IPAddress(val1, module.version, flags=INET_PTON)
  File "/home/petrache/VENV/py3_venv/local/lib/python3.6/site-packages/netaddr/ip/__init__.py", line 314, in __init__
    % (addr, self._module.version))
netaddr.core.AddrFormatError: base address '' is not IPv4

During handling of the above exception, another exception occurred:

Traceback (most recent call last):
  File "/home/petrache/VENV/py3_venv/local/lib/python3.6/site-packages/netaddr/strategy/ipv4.py", line 265, in expand_partial_address
    tokens = ['%d' % int(addr)]
ValueError: invalid literal for int() with base 10: ''

During handling of the above exception, another exception occurred:

Traceback (most recent call last):
  File "/home/petrache/VENV/py3_venv/local/lib/python3.6/site-packages/netaddr/ip/__init__.py", line 928, in __init__
    implicit_prefix, flags)
  File "/home/petrache/VENV/py3_venv/local/lib/python3.6/site-packages/netaddr/ip/__init__.py", line 795, in parse_ip_network
    expanded_addr = _ipv4.expand_partial_address(val1)
  File "/home/petrache/VENV/py3_venv/local/lib/python3.6/site-packages/netaddr/strategy/ipv4.py", line 267, in expand_partial_address
    raise error
netaddr.core.AddrFormatError: invalid partial IPv4 address: ''!

During handling of the above exception, another exception occurred:

Traceback (most recent call last):
  File "/home/petrache/VENV/py3_venv/local/lib/python3.6/site-packages/nornir/core/task.py", line 67, in start
    r = self.task(self, **self.params)
  File "/home/petrache/VENV/py3_venv/local/lib/python3.6/site-packages/nornir/plugins/tasks/networking/napalm_get.py", line 61, in napalm_get
    result[g] = method(**options)
  File "/home/petrache/VENV/py3_venv/src/napalm/napalm/eos/eos.py", line 1159, in get_route_to
    if IPNetwork(destination).version == 6:
  File "/home/petrache/VENV/py3_venv/local/lib/python3.6/site-packages/netaddr/ip/__init__.py", line 938, in __init__
    raise AddrFormatError('invalid IPNetwork %s' % addr)
netaddr.core.AddrFormatError: invalid IPNetwork 

2019-08-21 11:31:29,096 - nornir.core.task -    ERROR -      start() - Host 'arista1': task 'napalm_get' failed with traceback:
Traceback (most recent call last):
  File "/home/petrache/VENV/py3_venv/local/lib/python3.6/site-packages/netaddr/strategy/ipv4.py", line 125, in str_to_int
    return _struct.unpack('>I', _inet_pton(AF_INET, addr))[0]
OSError: illegal IP address string passed to inet_pton

During handling of the above exception, another exception occurred:

Traceback (most recent call last):
  File "/home/petrache/VENV/py3_venv/local/lib/python3.6/site-packages/netaddr/ip/__init__.py", line 311, in __init__
    self._value = self._module.str_to_int(addr, flags)
  File "/home/petrache/VENV/py3_venv/local/lib/python3.6/site-packages/netaddr/strategy/ipv4.py", line 129, in str_to_int
    raise AddrFormatError('%r is not a valid IPv4 address string!' % addr)
netaddr.core.AddrFormatError: '' is not a valid IPv4 address string!

During handling of the above exception, another exception occurred:

Traceback (most recent call last):
  File "/home/petrache/VENV/py3_venv/local/lib/python3.6/site-packages/netaddr/ip/__init__.py", line 791, in parse_ip_network
    ip = IPAddress(val1, module.version, flags=INET_PTON)
  File "/home/petrache/VENV/py3_venv/local/lib/python3.6/site-packages/netaddr/ip/__init__.py", line 314, in __init__
    % (addr, self._module.version))
netaddr.core.AddrFormatError: base address '' is not IPv4

During handling of the above exception, another exception occurred:

Traceback (most recent call last):
  File "/home/petrache/VENV/py3_venv/local/lib/python3.6/site-packages/netaddr/strategy/ipv4.py", line 265, in expand_partial_address
    tokens = ['%d' % int(addr)]
ValueError: invalid literal for int() with base 10: ''

During handling of the above exception, another exception occurred:

Traceback (most recent call last):
  File "/home/petrache/VENV/py3_venv/local/lib/python3.6/site-packages/netaddr/ip/__init__.py", line 928, in __init__
    implicit_prefix, flags)
  File "/home/petrache/VENV/py3_venv/local/lib/python3.6/site-packages/netaddr/ip/__init__.py", line 795, in parse_ip_network
    expanded_addr = _ipv4.expand_partial_address(val1)
  File "/home/petrache/VENV/py3_venv/local/lib/python3.6/site-packages/netaddr/strategy/ipv4.py", line 267, in expand_partial_address
    raise error
netaddr.core.AddrFormatError: invalid partial IPv4 address: ''!

During handling of the above exception, another exception occurred:

Traceback (most recent call last):
  File "/home/petrache/VENV/py3_venv/local/lib/python3.6/site-packages/nornir/core/task.py", line 67, in start
    r = self.task(self, **self.params)
  File "/home/petrache/VENV/py3_venv/local/lib/python3.6/site-packages/nornir/plugins/tasks/networking/napalm_get.py", line 61, in napalm_get
    result[g] = method(**options)
  File "/home/petrache/VENV/py3_venv/src/napalm/napalm/eos/eos.py", line 1159, in get_route_to
    if IPNetwork(destination).version == 6:
  File "/home/petrache/VENV/py3_venv/local/lib/python3.6/site-packages/netaddr/ip/__init__.py", line 938, in __init__
    raise AddrFormatError('invalid IPNetwork %s' % addr)
netaddr.core.AddrFormatError: invalid IPNetwork 

2019-08-21 11:33:53,418 -  nornir.core -     INFO -        run() - Running task 'napalm_get' with args {'getters': ['arp_table']} on 6 hosts
2019-08-21 11:33:58,706 -  nornir.core -     INFO -        run() - Running task 'napalm_get' with args {'getters': ['get_route_to']} on 6 hosts
2019-08-21 11:33:58,709 - nornir.core.task -    ERROR -      start() - Host 'cisco3': task 'napalm_get' failed with traceback:
Traceback (most recent call last):
  File "/home/petrache/VENV/py3_venv/local/lib/python3.6/site-packages/nornir/core/task.py", line 67, in start
    r = self.task(self, **self.params)
  File "/home/petrache/VENV/py3_venv/local/lib/python3.6/site-packages/nornir/plugins/tasks/networking/napalm_get.py", line 61, in napalm_get
    result[g] = method(**options)
  File "/home/petrache/VENV/py3_venv/src/napalm/napalm/base/base.py", line 1070, in get_route_to
    raise NotImplementedError
NotImplementedError

2019-08-21 11:33:58,710 - nornir.core.task -    ERROR -      start() - Host 'cisco4': task 'napalm_get' failed with traceback:
Traceback (most recent call last):
  File "/home/petrache/VENV/py3_venv/local/lib/python3.6/site-packages/nornir/core/task.py", line 67, in start
    r = self.task(self, **self.params)
  File "/home/petrache/VENV/py3_venv/local/lib/python3.6/site-packages/nornir/plugins/tasks/networking/napalm_get.py", line 61, in napalm_get
    result[g] = method(**options)
  File "/home/petrache/VENV/py3_venv/src/napalm/napalm/base/base.py", line 1070, in get_route_to
    raise NotImplementedError
NotImplementedError

2019-08-21 11:33:59,132 - nornir.core.task -    ERROR -      start() - Host 'arista1': task 'napalm_get' failed with traceback:
Traceback (most recent call last):
  File "/home/petrache/VENV/py3_venv/local/lib/python3.6/site-packages/netaddr/strategy/ipv4.py", line 125, in str_to_int
    return _struct.unpack('>I', _inet_pton(AF_INET, addr))[0]
OSError: illegal IP address string passed to inet_pton

During handling of the above exception, another exception occurred:

Traceback (most recent call last):
  File "/home/petrache/VENV/py3_venv/local/lib/python3.6/site-packages/netaddr/ip/__init__.py", line 311, in __init__
    self._value = self._module.str_to_int(addr, flags)
  File "/home/petrache/VENV/py3_venv/local/lib/python3.6/site-packages/netaddr/strategy/ipv4.py", line 129, in str_to_int
    raise AddrFormatError('%r is not a valid IPv4 address string!' % addr)
netaddr.core.AddrFormatError: '' is not a valid IPv4 address string!

During handling of the above exception, another exception occurred:

Traceback (most recent call last):
  File "/home/petrache/VENV/py3_venv/local/lib/python3.6/site-packages/netaddr/ip/__init__.py", line 791, in parse_ip_network
    ip = IPAddress(val1, module.version, flags=INET_PTON)
  File "/home/petrache/VENV/py3_venv/local/lib/python3.6/site-packages/netaddr/ip/__init__.py", line 314, in __init__
    % (addr, self._module.version))
netaddr.core.AddrFormatError: base address '' is not IPv4

During handling of the above exception, another exception occurred:

Traceback (most recent call last):
  File "/home/petrache/VENV/py3_venv/local/lib/python3.6/site-packages/netaddr/strategy/ipv4.py", line 265, in expand_partial_address
    tokens = ['%d' % int(addr)]
ValueError: invalid literal for int() with base 10: ''

During handling of the above exception, another exception occurred:

Traceback (most recent call last):
  File "/home/petrache/VENV/py3_venv/local/lib/python3.6/site-packages/netaddr/ip/__init__.py", line 928, in __init__
    implicit_prefix, flags)
  File "/home/petrache/VENV/py3_venv/local/lib/python3.6/site-packages/netaddr/ip/__init__.py", line 795, in parse_ip_network
    expanded_addr = _ipv4.expand_partial_address(val1)
  File "/home/petrache/VENV/py3_venv/local/lib/python3.6/site-packages/netaddr/strategy/ipv4.py", line 267, in expand_partial_address
    raise error
netaddr.core.AddrFormatError: invalid partial IPv4 address: ''!

During handling of the above exception, another exception occurred:

Traceback (most recent call last):
  File "/home/petrache/VENV/py3_venv/local/lib/python3.6/site-packages/nornir/core/task.py", line 67, in start
    r = self.task(self, **self.params)
  File "/home/petrache/VENV/py3_venv/local/lib/python3.6/site-packages/nornir/plugins/tasks/networking/napalm_get.py", line 61, in napalm_get
    result[g] = method(**options)
  File "/home/petrache/VENV/py3_venv/src/napalm/napalm/eos/eos.py", line 1159, in get_route_to
    if IPNetwork(destination).version == 6:
  File "/home/petrache/VENV/py3_venv/local/lib/python3.6/site-packages/netaddr/ip/__init__.py", line 938, in __init__
    raise AddrFormatError('invalid IPNetwork %s' % addr)
netaddr.core.AddrFormatError: invalid IPNetwork 

2019-08-21 11:33:59,133 - nornir.core.task -    ERROR -      start() - Host 'arista4': task 'napalm_get' failed with traceback:
Traceback (most recent call last):
  File "/home/petrache/VENV/py3_venv/local/lib/python3.6/site-packages/netaddr/strategy/ipv4.py", line 125, in str_to_int
    return _struct.unpack('>I', _inet_pton(AF_INET, addr))[0]
OSError: illegal IP address string passed to inet_pton

During handling of the above exception, another exception occurred:

Traceback (most recent call last):
  File "/home/petrache/VENV/py3_venv/local/lib/python3.6/site-packages/netaddr/ip/__init__.py", line 311, in __init__
    self._value = self._module.str_to_int(addr, flags)
  File "/home/petrache/VENV/py3_venv/local/lib/python3.6/site-packages/netaddr/strategy/ipv4.py", line 129, in str_to_int
    raise AddrFormatError('%r is not a valid IPv4 address string!' % addr)
netaddr.core.AddrFormatError: '' is not a valid IPv4 address string!

During handling of the above exception, another exception occurred:

Traceback (most recent call last):
  File "/home/petrache/VENV/py3_venv/local/lib/python3.6/site-packages/netaddr/ip/__init__.py", line 791, in parse_ip_network
    ip = IPAddress(val1, module.version, flags=INET_PTON)
  File "/home/petrache/VENV/py3_venv/local/lib/python3.6/site-packages/netaddr/ip/__init__.py", line 314, in __init__
    % (addr, self._module.version))
netaddr.core.AddrFormatError: base address '' is not IPv4

During handling of the above exception, another exception occurred:

Traceback (most recent call last):
  File "/home/petrache/VENV/py3_venv/local/lib/python3.6/site-packages/netaddr/strategy/ipv4.py", line 265, in expand_partial_address
    tokens = ['%d' % int(addr)]
ValueError: invalid literal for int() with base 10: ''

During handling of the above exception, another exception occurred:

Traceback (most recent call last):
  File "/home/petrache/VENV/py3_venv/local/lib/python3.6/site-packages/netaddr/ip/__init__.py", line 928, in __init__
    implicit_prefix, flags)
  File "/home/petrache/VENV/py3_venv/local/lib/python3.6/site-packages/netaddr/ip/__init__.py", line 795, in parse_ip_network
    expanded_addr = _ipv4.expand_partial_address(val1)
  File "/home/petrache/VENV/py3_venv/local/lib/python3.6/site-packages/netaddr/strategy/ipv4.py", line 267, in expand_partial_address
    raise error
netaddr.core.AddrFormatError: invalid partial IPv4 address: ''!

During handling of the above exception, another exception occurred:

Traceback (most recent call last):
  File "/home/petrache/VENV/py3_venv/local/lib/python3.6/site-packages/nornir/core/task.py", line 67, in start
    r = self.task(self, **self.params)
  File "/home/petrache/VENV/py3_venv/local/lib/python3.6/site-packages/nornir/plugins/tasks/networking/napalm_get.py", line 61, in napalm_get
    result[g] = method(**options)
  File "/home/petrache/VENV/py3_venv/src/napalm/napalm/eos/eos.py", line 1159, in get_route_to
    if IPNetwork(destination).version == 6:
  File "/home/petrache/VENV/py3_venv/local/lib/python3.6/site-packages/netaddr/ip/__init__.py", line 938, in __init__
    raise AddrFormatError('invalid IPNetwork %s' % addr)
netaddr.core.AddrFormatError: invalid IPNetwork 

2019-08-21 11:33:59,135 - nornir.core.task -    ERROR -      start() - Host 'arista3': task 'napalm_get' failed with traceback:
Traceback (most recent call last):
  File "/home/petrache/VENV/py3_venv/local/lib/python3.6/site-packages/netaddr/strategy/ipv4.py", line 125, in str_to_int
    return _struct.unpack('>I', _inet_pton(AF_INET, addr))[0]
OSError: illegal IP address string passed to inet_pton

During handling of the above exception, another exception occurred:

Traceback (most recent call last):
  File "/home/petrache/VENV/py3_venv/local/lib/python3.6/site-packages/netaddr/ip/__init__.py", line 311, in __init__
    self._value = self._module.str_to_int(addr, flags)
  File "/home/petrache/VENV/py3_venv/local/lib/python3.6/site-packages/netaddr/strategy/ipv4.py", line 129, in str_to_int
    raise AddrFormatError('%r is not a valid IPv4 address string!' % addr)
netaddr.core.AddrFormatError: '' is not a valid IPv4 address string!

During handling of the above exception, another exception occurred:

Traceback (most recent call last):
  File "/home/petrache/VENV/py3_venv/local/lib/python3.6/site-packages/netaddr/ip/__init__.py", line 791, in parse_ip_network
    ip = IPAddress(val1, module.version, flags=INET_PTON)
  File "/home/petrache/VENV/py3_venv/local/lib/python3.6/site-packages/netaddr/ip/__init__.py", line 314, in __init__
    % (addr, self._module.version))
netaddr.core.AddrFormatError: base address '' is not IPv4

During handling of the above exception, another exception occurred:

Traceback (most recent call last):
  File "/home/petrache/VENV/py3_venv/local/lib/python3.6/site-packages/netaddr/strategy/ipv4.py", line 265, in expand_partial_address
    tokens = ['%d' % int(addr)]
ValueError: invalid literal for int() with base 10: ''

During handling of the above exception, another exception occurred:

Traceback (most recent call last):
  File "/home/petrache/VENV/py3_venv/local/lib/python3.6/site-packages/netaddr/ip/__init__.py", line 928, in __init__
    implicit_prefix, flags)
  File "/home/petrache/VENV/py3_venv/local/lib/python3.6/site-packages/netaddr/ip/__init__.py", line 795, in parse_ip_network
    expanded_addr = _ipv4.expand_partial_address(val1)
  File "/home/petrache/VENV/py3_venv/local/lib/python3.6/site-packages/netaddr/strategy/ipv4.py", line 267, in expand_partial_address
    raise error
netaddr.core.AddrFormatError: invalid partial IPv4 address: ''!

During handling of the above exception, another exception occurred:

Traceback (most recent call last):
  File "/home/petrache/VENV/py3_venv/local/lib/python3.6/site-packages/nornir/core/task.py", line 67, in start
    r = self.task(self, **self.params)
  File "/home/petrache/VENV/py3_venv/local/lib/python3.6/site-packages/nornir/plugins/tasks/networking/napalm_get.py", line 61, in napalm_get
    result[g] = method(**options)
  File "/home/petrache/VENV/py3_venv/src/napalm/napalm/eos/eos.py", line 1159, in get_route_to
    if IPNetwork(destination).version == 6:
  File "/home/petrache/VENV/py3_venv/local/lib/python3.6/site-packages/netaddr/ip/__init__.py", line 938, in __init__
    raise AddrFormatError('invalid IPNetwork %s' % addr)
netaddr.core.AddrFormatError: invalid IPNetwork 

2019-08-21 11:33:59,163 - nornir.core.task -    ERROR -      start() - Host 'arista2': task 'napalm_get' failed with traceback:
Traceback (most recent call last):
  File "/home/petrache/VENV/py3_venv/local/lib/python3.6/site-packages/netaddr/strategy/ipv4.py", line 125, in str_to_int
    return _struct.unpack('>I', _inet_pton(AF_INET, addr))[0]
OSError: illegal IP address string passed to inet_pton

During handling of the above exception, another exception occurred:

Traceback (most recent call last):
  File "/home/petrache/VENV/py3_venv/local/lib/python3.6/site-packages/netaddr/ip/__init__.py", line 311, in __init__
    self._value = self._module.str_to_int(addr, flags)
  File "/home/petrache/VENV/py3_venv/local/lib/python3.6/site-packages/netaddr/strategy/ipv4.py", line 129, in str_to_int
    raise AddrFormatError('%r is not a valid IPv4 address string!' % addr)
netaddr.core.AddrFormatError: '' is not a valid IPv4 address string!

During handling of the above exception, another exception occurred:

Traceback (most recent call last):
  File "/home/petrache/VENV/py3_venv/local/lib/python3.6/site-packages/netaddr/ip/__init__.py", line 791, in parse_ip_network
    ip = IPAddress(val1, module.version, flags=INET_PTON)
  File "/home/petrache/VENV/py3_venv/local/lib/python3.6/site-packages/netaddr/ip/__init__.py", line 314, in __init__
    % (addr, self._module.version))
netaddr.core.AddrFormatError: base address '' is not IPv4

During handling of the above exception, another exception occurred:

Traceback (most recent call last):
  File "/home/petrache/VENV/py3_venv/local/lib/python3.6/site-packages/netaddr/strategy/ipv4.py", line 265, in expand_partial_address
    tokens = ['%d' % int(addr)]
ValueError: invalid literal for int() with base 10: ''

During handling of the above exception, another exception occurred:

Traceback (most recent call last):
  File "/home/petrache/VENV/py3_venv/local/lib/python3.6/site-packages/netaddr/ip/__init__.py", line 928, in __init__
    implicit_prefix, flags)
  File "/home/petrache/VENV/py3_venv/local/lib/python3.6/site-packages/netaddr/ip/__init__.py", line 795, in parse_ip_network
    expanded_addr = _ipv4.expand_partial_address(val1)
  File "/home/petrache/VENV/py3_venv/local/lib/python3.6/site-packages/netaddr/strategy/ipv4.py", line 267, in expand_partial_address
    raise error
netaddr.core.AddrFormatError: invalid partial IPv4 address: ''!

During handling of the above exception, another exception occurred:

Traceback (most recent call last):
  File "/home/petrache/VENV/py3_venv/local/lib/python3.6/site-packages/nornir/core/task.py", line 67, in start
    r = self.task(self, **self.params)
  File "/home/petrache/VENV/py3_venv/local/lib/python3.6/site-packages/nornir/plugins/tasks/networking/napalm_get.py", line 61, in napalm_get
    result[g] = method(**options)
  File "/home/petrache/VENV/py3_venv/src/napalm/napalm/eos/eos.py", line 1159, in get_route_to
    if IPNetwork(destination).version == 6:
  File "/home/petrache/VENV/py3_venv/local/lib/python3.6/site-packages/netaddr/ip/__init__.py", line 938, in __init__
    raise AddrFormatError('invalid IPNetwork %s' % addr)
netaddr.core.AddrFormatError: invalid IPNetwork 

2019-08-21 11:43:41,268 -  nornir.core -     INFO -        run() - Running task 'napalm_get' with args {'getters': ['arp_table']} on 6 hosts
2019-08-21 11:44:20,680 -  nornir.core -     INFO -        run() - Running task 'napalm_get' with args {'getters': ['arp_table']} on 6 hosts
2019-08-21 11:44:26,215 -  nornir.core -     INFO -        run() - Running task 'netmiko_send_command' with args {'command_string': 'show run | include ip route 0.0.0.0'} on 6 hosts
2019-08-21 11:45:01,043 -  nornir.core -     INFO -        run() - Running task 'napalm_get' with args {'getters': ['arp_table']} on 6 hosts
2019-08-21 11:45:06,523 -  nornir.core -     INFO -        run() - Running task 'netmiko_send_command' with args {'command_string': 'show run | include ip route 0.0.0.0'} on 6 hosts
2019-08-21 11:50:30,584 -  nornir.core -     INFO -        run() - Running task 'napalm_get' with args {'getters': ['arp_table']} on 6 hosts
2019-08-21 11:50:36,104 -  nornir.core -     INFO -        run() - Running task 'netmiko_send_command' with args {'command_string': 'show run | include ip route 0.0.0.0'} on 6 hosts
2019-08-21 11:51:53,835 -  nornir.core -     INFO -        run() - Running task 'napalm_get' with args {'getters': ['arp_table']} on 6 hosts
2019-08-21 11:51:59,311 -  nornir.core -     INFO -        run() - Running task 'netmiko_send_command' with args {'command_string': 'show run | include ip route 0.0.0.0'} on 6 hosts
2019-08-21 11:54:21,152 -  nornir.core -     INFO -        run() - Running task 'napalm_get' with args {'getters': ['arp_table']} on 6 hosts
2019-08-21 11:54:26,575 -  nornir.core -     INFO -        run() - Running task 'netmiko_send_command' with args {'command_string': 'show run | include ip route 0.0.0.0'} on 6 hosts
2019-08-21 11:56:20,298 -  nornir.core -     INFO -        run() - Running task 'napalm_get' with args {'getters': ['arp_table']} on 6 hosts
2019-08-21 11:56:25,724 -  nornir.core -     INFO -        run() - Running task 'netmiko_send_command' with args {'command_string': 'show run | include ip route 0.0.0.0'} on 6 hosts
2019-08-21 11:57:38,127 -  nornir.core -     INFO -        run() - Running task 'napalm_get' with args {'getters': ['arp_table']} on 6 hosts
2019-08-21 11:57:43,604 -  nornir.core -     INFO -        run() - Running task 'netmiko_send_command' with args {'command_string': 'show run | include ip route 0.0.0.0'} on 6 hosts
2019-08-21 11:58:56,246 -  nornir.core -     INFO -        run() - Running task 'napalm_get' with args {'getters': ['arp_table']} on 6 hosts
2019-08-21 11:59:01,732 -  nornir.core -     INFO -        run() - Running task 'netmiko_send_command' with args {'command_string': 'show run | include ip route 0.0.0.0'} on 6 hosts
2019-08-21 12:02:13,168 -  nornir.core -     INFO -        run() - Running task 'napalm_get' with args {'getters': ['arp_table']} on 6 hosts
2019-08-21 12:02:18,351 -  nornir.core -     INFO -        run() - Running task 'netmiko_send_command' with args {'command_string': 'show run | include ip route 0.0.0.0'} on 6 hosts
2019-08-21 12:05:38,691 -  nornir.core -     INFO -        run() - Running task 'napalm_get' with args {'getters': ['arp_table']} on 6 hosts
2019-08-21 12:05:44,212 -  nornir.core -     INFO -        run() - Running task 'netmiko_send_command' with args {'command_string': 'show run | include ip route 0.0.0.0'} on 6 hosts
2019-08-21 12:07:38,267 -  nornir.core -     INFO -        run() - Running task 'napalm_get' with args {'getters': ['arp_table']} on 6 hosts
2019-08-21 12:07:43,791 -  nornir.core -     INFO -        run() - Running task 'netmiko_send_command' with args {'command_string': 'show run | include ip route 0.0.0.0'} on 6 hosts
2019-08-21 12:09:00,361 -  nornir.core -     INFO -        run() - Running task 'napalm_get' with args {'getters': ['arp_table']} on 6 hosts
2019-08-21 12:09:05,805 -  nornir.core -     INFO -        run() - Running task 'netmiko_send_command' with args {'command_string': 'show run | include ip route 0.0.0.0'} on 6 hosts
2019-08-21 12:11:36,207 -  nornir.core -     INFO -        run() - Running task 'napalm_get' with args {'getters': ['arp_table']} on 6 hosts
2019-08-21 12:11:41,627 -  nornir.core -     INFO -        run() - Running task 'netmiko_send_command' with args {'command_string': 'show run | include ip route 0.0.0.0'} on 6 hosts
2019-08-21 12:13:03,693 -  nornir.core -     INFO -        run() - Running task 'napalm_get' with args {'getters': ['arp_table']} on 6 hosts
2019-08-21 12:13:09,173 -  nornir.core -     INFO -        run() - Running task 'netmiko_send_command' with args {'command_string': 'show run | include ip route 0.0.0.0'} on 6 hosts
2019-09-18 13:45:28,074 -  nornir.core -     INFO -        run() - Running task 'napalm_get' with args {'getters': ['arp_table']} on 6 hosts
2019-09-18 13:45:33,508 -  nornir.core -     INFO -        run() - Running task 'netmiko_send_command' with args {'command_string': 'show run | include ip route 0.0.0.0'} on 6 hosts
